Workbook

Sheet Cover
A2: Saltbrush Beverage Co., December 2025 Close
A4: The December 2025 month end close behind Saltbrush Beverage Co.'s FY2025 statements
A6: Fiscal years covered: FY2025
A8: Industry: Consumer products manufacturer (beverages)
A9: Role fit: Staff accountant, Financial reporting, FP&A
A10: The close ties to the FY2025 year end already reported in the Saltbrush Beverage Co. three statement model.
A12: Fictional company. All figures are illustrative and were built for this portfolio.
A13: Prepared by George Murad
A15: Contents
A16: Cover
A17: Close Checklist
A18: Unadjusted TB
... A32: Formula, pulls from another sheet

Sheet Close Checklist
A1: Saltbrush Beverage Co., December 2025 Close
A2: Close Checklist
A3: (whole dollars, except the Statements sheet, which is $ in thousands) December 2025 close
B5: Supporting sheet | C5: Status
A6: Cutoff (goods received not invoiced) | B6: Inventory | C6: =IF(ABS('Inventory'!B12)<0.5,"Done","Open") -> Done
A7: Accruals (payroll, payroll taxes, freight, utilities, interest) | B7: Accruals and Prepaids | C7: =IF(ABS('Accruals and Prepaids'!B16)<0.5,"Done","Open") -> Done
A8: Prepaids (insurance amortization) | B8: Accruals and Prepaids | C8: =IF(ABS('Accruals and Prepaids'!D22)<0.5,"Done","Open") -> Done
A9: Depreciation (December, by asset class) | B9: Fixed Assets | C9: =IF(ABS('Fixed Assets'!B11)<0.5,"Done","Open") -> Done
A10: Inventory count (book versus physical count) | B10: Inventory | C10: =IF(ABS('Inventory'!B12)<0.5,"Done","Open") -> Done
A11: Standard cost variances (close out to the income statement) | B11: Inventory | C11: =IF(ABS('Inventory'!B18)<0.5,"Done","Open") -> Done
A12: Bank reconciliation | B12: Bank Reconciliation | C12: =IF(ABS('Bank Reconciliation'!B13)<0.5,"Done","Open") -> Done
A13: Subledger ties (AR aging, AP subledger) | B13: Subledgers | C13: =IF(ABS(('Subledgers'!B24+'Subledgers'!B34))<0.5,"Done","Open") -> Done
A14: Tax provision (December income tax) | B14: Adjusted TB | C14: =IF(ABS(('Adjusted TB'!F36-1198000))<0.5,"Done","Open") -> Done
A15: Review (all close checks read OK) | B15: Checks | C15: =IF('Checks'!B3="ALL OK","Done","Open") -> Done
A16: Statements (FY2025 income statement and balance sheet) | B16: Statements | C16: =IF(ABS(('Statements'!B29-'Statements'!B39))<0.5,"Done","Open") -> Done
A17: Checks passing | B17: Checks | C17: =45 -> 45
A18: Close checklist steps | B18: Checklist | C18: =11 -> 11

Sheet Unadjusted TB
A1: Saltbrush Beverage Co., December 2025 Close
A2: Unadjusted Trial Balance
A3: (whole dollars, except the Statements sheet, which is $ in thousands) December 31, 2025, before adjusting entries
B5: Debit | C5: Credit
A6: Cash | B6: =2529245 -> 2529245 | C6: =0 -> 0
A7: Accounts receivable, gross | B7: =7683176.422431437 -> 7683176.4 | C7: =0 -> 0
A8: Allowance for doubtful accounts | B8: =0 -> 0 | C8: =153176.4224314368 -> 153176.42
A9: Inventory | B9: =6843000 -> 6843000 | C9: =0 -> 0
A10: Prepaid expenses | B10: =786000 -> 786000 | C10: =0 -> 0
A11: Production variance clearing | B11: =190333.3333333333 -> 190333.33 | C11: =0 -> 0
A12: Property, plant and equipment, gross | B12: =40300000 -> 40300000 | C12: =0 -> 0
A13: Accumulated depreciation | B13: =0 -> 0 | C13: =19817250 -> 19817250
A14: Accounts payable | B14: =0 -> 0 | C14: =5519000 -> 5519000
A15: Accrued payroll | B15: =0 -> 0 | C15: =0 -> 0
A16: Accrued payroll taxes | B16: =0 -> 0 | C16: =0 -> 0
A17: Accrued freight | B17: =0 -> 0 | C17: =0 -> 0
A18: Accrued utilities | B18: =0 -> 0 | C18: =0 -> 0
A19: Accrued interest | B19: =0 -> 0 | C19: =0 -> 0
A20: Income tax payable | B20: =0 -> 0 | C20: =400000 -> 400000
A21: Accrued bonus (annual pool) | B21: =0 -> 0 | C21: =1100000 -> 1100000
A22: Accrued vacation | B22: =0 -> 0 | C22: =600000 -> 600000
A23: Other accrued expenses | B23: =0 -> 0 | C23: =387500.1737156371 -> 387500.17
A24: Revolver | B24: =0 -> 0 | C24: =0 -> 0
A25: Equipment loan | B25: =0 -> 0 | C25: =4500000 -> 4500000
A26: Common stock and paid in capital | B26: =0 -> 0 | C26: =6000000 -> 6000000
A27: Retained earnings, beginning of year | B27: =0 -> 0 | C27: =15368000 -> 15368000
A28: Revenue | B28: =0 -> 0 | C28: =72116000 -> 72116000
A29: Cost of sales at standard | B29: =44073615.01504137 -> 44073615 | C29: =0 -> 0
A30: Manufacturing variances | B30: =2093666.6666666667 -> 2093666.7 | C30: =0 -> 0
A31: Selling and distribution | B31: =8354000 -> 8354000 | C31: =0 -> 0
A32: Marketing | B32: =4688000 -> 4688000 | C32: =0 -> 0
A33: General and administrative | B33: =4690426.056387194 -> 4690426.1 | C33: =0 -> 0
A34: Depreciation | B34: =1845250 -> 1845250 | C34: =0 -> 0
A35: Interest expense | B35: =388687.5 -> 388687.5 | C35: =0 -> 0
A36: Income tax expense | B36: =1495526.6022870655 -> 1495526.6 | C36: =0 -> 0
A37: Total | B37: =(B6+B7+B8+B9+B10+B11+B12+B13+B14+B15+B16+B17+B18+B19+B20+B21+B22+B23+B24+B25+B26+B27+B28+B29+B30+B31+B32+B33+B34+B35+B36) -> 1.2596093e+08 | C37: =(C6+C7+C8+C9+C10+C11+C12+C13+C14+C15+C16+C17+C18+C19+C20+C21+C22+C23+C24+C25+C26+C27+C28+C29+C30+C31+C32+C33+C34+C35+C36) -> 1.2596093e+08

Sheet Adjusting Entries
A1: Saltbrush Beverage Co., December 2025 Close
A2: Adjusting Entries
A3: (whole dollars, except the Statements sheet, which is $ in thousands) Numbered journal, December 31, 2025
B5: JE # | C5: Date | D5: Debit | E5: Credit | F5: Description | G5: Supporting sheet
A6: JE 01 Dec 31, 2025 Accrue unpaid December payroll (3 days of the $610,000 biweekly companywide payroll run, split 71% to cost of sales and 29% to G&A by the model's own FY2025 expense shares) (supporting: Accruals and Prepaids)
A7: Cost of sales at standard | B7: =1 -> 1 | C7: Dec 31, 2025 | D7: =92322.3269471652 -> 92322.327 | E7: =0 -> 0 | F7: Accrue unpaid December payroll (3 days of the $610,000 biweekly companywide payroll run, split 71% to cost of sales and 29% to G&A by the model's own FY2025 expense shares) | G7: Accruals and Prepaids
A8: General and administrative | B8: =1 -> 1 | C8: Dec 31, 2025 | D8: =38391.9587671205 -> 38391.959 | E8: =0 -> 0 | F8: Accrue unpaid December payroll (3 days of the $610,000 biweekly companywide payroll run, split 71% to cost of sales and 29% to G&A by the model's own FY2025 expense shares) | G8: Accruals and Prepaids
A9: Accrued payroll | B9: =1 -> 1 | C9: Dec 31, 2025 | D9: =0 -> 0 | E9: =130714.2857142857 -> 130714.29 | F9: Accrue unpaid December payroll (3 days of the $610,000 biweekly companywide payroll run, split 71% to cost of sales and 29% to G&A by the model's own FY2025 expense shares) | G9: Accruals and Prepaids
A10: JE 02 Dec 31, 2025 Accrue payroll taxes on the unpaid December payroll, at 7.65%, split the same way as JE 01 (supporting: Accruals and Prepaids)
A11: Cost of sales at standard | B11: =2 -> 2 | C11: Dec 31, 2025 | D11: =7062.6580114581 -> 7062.658 | E11: =0 -> 0 | F11: Accrue payroll taxes on the unpaid December payroll, at 7.65%, split the same way as JE 01 | G11: Accruals and Prepaids
A12: General and administrative | B12: =2 -> 2 | C12: Dec 31, 2025 | D12: =2936.9848456847 -> 2936.9848 | E12: =0 -> 0 | F12: Accrue payroll taxes on the unpaid December payroll, at 7.65%, split the same way as JE 01 | G12: Accruals and Prepaids
A13: Accrued payroll taxes | B13: =2 -> 2 | C13: Dec 31, 2025 | D13: =0 -> 0 | E13: =9999.6428571429 -> 9999.6429 | F13: Accrue payroll taxes on the unpaid December payroll, at 7.65%, split the same way as JE 01 | G13: Accruals and Prepaids
A14: JE 03 Dec 31, 2025 Accrue two weeks of December freight not yet invoiced (supporting: Accruals and Prepaids)
A15: Selling and distribution | B15: =3 -> 3 | C15: Dec 31, 2025 | D15: =300000 -> 300000 | E15: =0 -> 0 | F15: Accrue two weeks of December freight not yet invoiced | G15: Accruals and Prepaids
A16: Accrued freight | B16: =3 -> 3 | C16: Dec 31, 2025 | D16: =0 -> 0 | E16: =300000 -> 300000 | F16: Accrue two weeks of December freight not yet invoiced | G16: Accruals and Prepaids
A17: JE 04 Dec 31, 2025 Accrue December utilities (supporting: Accruals and Prepaids)
A18: General and administrative | B18: =4 -> 4 | C18: Dec 31, 2025 | D18: =129000 -> 129000 | E18: =0 -> 0 | F18: Accrue December utilities | G18: Accruals and Prepaids
A19: Accrued utilities | B19: =4 -> 4 | C19: Dec 31, 2025 | D19: =0 -> 0 | E19: =129000 -> 129000 | F19: Accrue December utilities | G19: Accruals and Prepaids
A20: JE 05 Dec 31, 2025 Amortize December prepaid insurance (supporting: Accruals and Prepaids)
A21: General and administrative | B21: =5 -> 5 | C21: Dec 31, 2025 | D21: =65000 -> 65000 | E21: =0 -> 0 | F21: Amortize December prepaid insurance | G21: Accruals and Prepaids
A22: Prepaid expenses | B22: =5 -> 5 | C22: Dec 31, 2025 | D22: =0 -> 0 | E22: =65000 -> 65000 | F22: Amortize December prepaid insurance | G22: Accruals and Prepaids
A23: JE 06 Dec 31, 2025 Record December depreciation (supporting: Fixed Assets)
A24: Depreciation | B24: =6 -> 6 | C24: Dec 31, 2025 | D24: =167750 -> 167750 | E24: =0 -> 0 | F24: Record December depreciation | G24: Fixed Assets
A25: Accumulated depreciation | B25: =6 -> 6 | C25: Dec 31, 2025 | D25: =0 -> 0 | E25: =167750 -> 167750 | F25: Record December depreciation | G25: Fixed Assets
A26: JE 07 Dec 31, 2025 Physical inventory count adjustment (shrinkage) (supporting: Inventory)
A27: Cost of sales at standard | B27: =7 -> 7 | C27: Dec 31, 2025 | D27: =50000 -> 50000 | E27: =0 -> 0 | F27: Physical inventory count adjustment (shrinkage) | G27: Inventory
A28: Inventory | B28: =7 -> 7 | C28: Dec 31, 2025 | D28: =0 -> 0 | E28: =50000 -> 50000 | F28: Physical inventory count adjustment (shrinkage) | G28: Inventory
A29: JE 08 Dec 31, 2025 Close December's manufacturing variance to the income statement, one twelfth of the FY2025 total (supporting: Inventory)
A30: Manufacturing variances | B30: =8 -> 8 | C30: Dec 31, 2025 | D30: =190333.3333333333 -> 190333.33 | E30: =0 -> 0 | F30: Close December's manufacturing variance to the income statement, one twelfth of the FY2025 total | G30: Inventory
A31: Production variance clearing | B31: =8 -> 8 | C31: Dec 31, 2025 | D31: =0 -> 0 | E31: =190333.3333333333 -> 190333.33 | F31: Close December's manufacturing variance to the income statement, one twelfth of the FY2025 total | G31: Inventory
A32: JE 09 Dec 31, 2025 Record December bank service charges (supporting: Bank Reconciliation)
A33: General and administrative | B33: =9 -> 9 | C33: Dec 31, 2025 | D33: =245 -> 245 | E33: =0 -> 0 | F33: Record December bank service charges | G33: Bank Reconciliation
A34: Cash | B34: =9 -> 9 | C34: Dec 31, 2025 | D34: =0 -> 0 | E34: =245 -> 245 | F34: Record December bank service charges | G34: Bank Reconciliation
A35: JE 10 Dec 31, 2025 Accrue December interest, equipment loan and revolver (supporting: Accruals and Prepaids)
A36: Interest expense | B36: =10 -> 10 | C36: Dec 31, 2025 | D36: =25312.5 -> 25312.5 | E36: =0 -> 0 | F36: Accrue December interest, equipment loan and revolver | G36: Accruals and Prepaids
A37: Accrued interest | B37: =10 -> 10 | C37: Dec 31, 2025 | D37: =0 -> 0 | E37: =25312.5 -> 25312.5 | F37: Accrue December interest, equipment loan and revolver | G37: Accruals and Prepaids
A38: JE 11 Dec 31, 2025 Record the allowance for doubtful accounts, by aging bucket loss rate (supporting: Subledgers)
A39: General and administrative | B39: =11 -> 11 | C39: Dec 31, 2025 | D39: =22000 -> 22000 | E39: =0 -> 0 | F39: Record the allowance for doubtful accounts, by aging bucket loss rate | G39: Subledgers
A40: Allowance for doubtful accounts | B40: =11 -> 11 | C40: Dec 31, 2025 | D40: =0 -> 0 | E40: =22000 -> 22000 | F40: Record the allowance for doubtful accounts, by aging bucket loss rate | G40: Subledgers
A41: JE 12 Dec 31, 2025 True up income tax payable at the model's 25.0% effective rate against the $400,000 tax estimate already accrued during the year (supporting: Adjusted TB)
...

Sheet Accruals and Prepaids
A1: Saltbrush Beverage Co., December 2025 Close
A2: Accruals and Prepaids
A3: (whole dollars, except the Statements sheet, which is $ in thousands) December 31, 2025. Accrued payroll, payroll taxes, freight and utilities reverse January 1, 2026; accrued interest and income tax payable clear when paid, not by reversal; the bonus pool, vacation and other accrued expenses carry forward, not reversing.
B5: Dec 1, after reversals | C5: December activity | D5: Dec 31 balance
A6: Accrued payroll (reverses January 1, 2026) | B6: ='Unadjusted TB'!C15 -> 0 | C6: =(('Adjusting Entries'!E9)-0) -> 130714.29 | D6: =(B6+C6) -> 130714.29
A7: Accrued payroll taxes (reverses January 1, 2026) | B7: ='Unadjusted TB'!C16 -> 0 | C7: =(('Adjusting Entries'!E13)-0) -> 9999.6429 | D7: =(B7+C7) -> 9999.6429
A8: Accrued freight (reverses January 1, 2026) | B8: ='Unadjusted TB'!C17 -> 0 | C8: =(('Adjusting Entries'!E16)-0) -> 300000 | D8: =(B8+C8) -> 300000
A9: Accrued utilities (reverses January 1, 2026) | B9: ='Unadjusted TB'!C18 -> 0 | C9: =(('Adjusting Entries'!E19)-0) -> 129000 | D9: =(B9+C9) -> 129000
A10: Accrued interest, equipment loan and revolver (clears at the next scheduled interest payment, not a January 1 reversal) | B10: ='Unadjusted TB'!C19 -> 0 | C10: =(('Adjusting Entries'!E37)-0) -> 25312.5 | D10: =(B10+C10) -> 25312.5
A11: Income tax payable (clears when the return is filed and paid, not a January 1 reversal) | B11: ='Unadjusted TB'!C20 -> 400000 | C11: =(0-('Adjusting Entries'!D43)) -> -297526.6 | D11: =(B11+C11) -> 102473.4
A12: Accrued bonus, annual pool (carries forward; one twelfth accrues each month, not a reversal) | B12: ='Unadjusted TB'!C21 -> 1100000 | C12: =(('Adjusting Entries'!E49)-0) -> 100000 | D12: =(B12+C12) -> 1200000
A13: Accrued vacation (carries forward, not reversing) | B13: ='Unadjusted TB'!C22 -> 600000 | C13: =(0-0) -> 0 | D13: =(B13+C13) -> 600000
A14: Other accrued expenses (carries forward, not reversing) | B14: ='Unadjusted TB'!C23 -> 387500.17 | C14: =(0-0) -> 0 | D14: =(B14+C14) -> 387500.17
A15: Total accrued liabilities, per this schedule | B15: =(B6+B7+B8+B9+B10+B11+B12+B13+B14) -> 2487500.2 | C15: =(C6+C7+C8+C9+C10+C11+C12+C13+C14) -> 397499.83 | D15: =(D6+D7+D8+D9+D10+D11+D12+D13+D14) -> 2885000
A16: Check: schedule total equals accrued liabilities on the adjusted TB | B16: =(D15-('Adjusted TB'!G15+'Adjusted TB'!G16+'Adjusted TB'!G17+'Adjusted TB'!G18+'Adjusted TB'!G19+'Adjusted TB'!G20+'Adjusted TB'!G21+'Adjusted TB'!G22+'Adjusted TB'!G23)) -> 0 | C16: =0 -> 0 | D16: =0 -> 0
A18: Prepaid insurance amortization
A19: Prepaid insurance, December 1, 2025 | B19: ='Unadjusted TB'!B10 -> 786000 | C19: =0 -> 0 | D19: =0 -> 0
A20: Less: December amortization | B20: =0 -> 0 | C20: ='Adjusting Entries'!E22 -> 65000 | D20: =0 -> 0
A21: Prepaid insurance, December 31, 2025 | B21: =0 -> 0 | C21: =0 -> 0 | D21: =('Unadjusted TB'!B10-'Adjusting Entries'!E22) -> 721000
A22: Check: ending balance equals prepaid expenses on the adjusted TB | B22: =0 -> 0 | C22: =0 -> 0 | D22: =(('Unadjusted TB'!B10-'Adjusting Entries'!E22)-721000) -> 0

Sheet Fixed Assets
A1: Saltbrush Beverage Co., December 2025 Close
A2: Fixed Assets
A3: (whole dollars, except the Statements sheet, which is $ in thousands) December depreciation roll forward by asset class
B5: Gross | C5: Accum. dep., Nov 30 | D5: December depreciation | E5: Accum. dep., Dec 31 | F5: Net PP&E
A6: Production equipment | B6: =24000000 -> 24000000 | C6: =(13842500-('Adjusting Entries'!D24*0.5)) -> 13758625 | D6: =('Adjusting Entries'!D24*0.5) -> 83875 | E6: =(C6+D6) -> 13842500 | F6: =(B6-E6) -> 10157500
A7: Canning line | B7: =11000000 -> 11000000 | C7: =(4905500-('Adjusting Entries'!D24*0.3)) -> 4855175 | D7: =('Adjusting Entries'!D24*0.3) -> 50325 | E7: =(C7+D7) -> 4905500 | F7: =(B7-E7) -> 6094500
A8: Delivery vehicles | B8: =3200000 -> 3200000 | C8: =(762200-('Adjusting Entries'!D24*0.12)) -> 742070 | D8: =('Adjusting Entries'!D24*0.12) -> 20130 | E8: =(C8+D8) -> 762200 | F8: =(B8-E8) -> 2437800
A9: Office and IT equipment | B9: =2100000 -> 2100000 | C9: =(474800-('Adjusting Entries'!D24*0.08)) -> 461380 | D9: =('Adjusting Entries'!D24*0.08) -> 13420 | E9: =(C9+D9) -> 474800 | F9: =(B9-E9) -> 1625200
A10: Total property, plant and equipment | B10: =(B6+B7+B8+B9) -> 40300000 | C10: =(C6+C7+C8+C9) -> 19817250 | D10: =(D6+D7+D8+D9) -> 167750 | E10: =(E6+E7+E8+E9) -> 19985000 | F10: =(F6+F7+F8+F9) -> 20315000
A11: Check: net PP&E per schedule equals PP&E net on the adjusted TB | B11: =(F10-('Adjusted TB'!F12-'Adjusted TB'!G13)) -> 0

Sheet Inventory
A1: Saltbrush Beverage Co., December 2025 Close
A2: Inventory
A3: (whole dollars, except the Statements sheet, which is $ in thousands) Book versus physical count, and the standard cost variance close out
B5: Amount
A6: Book inventory, per perpetual records (before cutoff and count) | B6: ='Unadjusted TB'!B9 -> 6843000
A7: Add: goods received in December, not yet invoiced (cutoff) | B7: ='Adjusting Entries'!D45 -> 215000
A8: Book inventory, before the physical count adjustment | B8: =(B6+B7) -> 7058000
A9: Physical inventory count, December 31, 2025 | B9: =7008000 -> 7008000
A10: Count adjustment (shrinkage) | B10: =(B9-B8) -> -50000
A11: Adjusted inventory, per adjusted trial balance | B11: =(B8+B10) -> 7008000
A12: Check: adjusted inventory equals the physical count | B12: =(B11-B9) -> 0
A14: Standard cost variance close out (December's share only; January through November already recognized in Manufacturing variances during the year)
A15: Production variance clearing, before close out (December's variance, unclosed) | B15: ='Unadjusted TB'!B11 -> 190333.33
A16: Close out to Manufacturing variances (income statement) | B16: =(-'Adjusting Entries'!D30) -> -190333.33
A17: Production variance clearing, after close out | B17: =(B15+B16) -> 0
A18: Check: manufacturing variances, year to date, equals the FY2025 total | B18: =(('Unadjusted TB'!B30+'Adjusting Entries'!D30)-2284000) -> 0

Sheet Bank Reconciliation
A1: Saltbrush Beverage Co., December 2025 Close
A2: Bank Reconciliation
A3: (whole dollars, except the Statements sheet, which is $ in thousands) Cash, December 31, 2025
B5: Amount
A6: Bank statement balance, December 31, 2025 (per the bank statement) | B6: =2565000 -> 2565000
A7: Add: deposits in transit | B7: =142650 -> 142650
A8: Less: outstanding checks | B8: =178650 -> 178650
A9: Adjusted bank balance | B9: =((B6+B7)-B8) -> 2529000
A10: Book balance, per unadjusted trial balance | B10: ='Unadjusted TB'!B6 -> 2529245
A11: Less: December bank service charges | B11: ='Adjusting Entries'!E34 -> 245
A12: Adjusted book balance | B12: =(B10-B11) -> 2529000
A13: Difference (adjusted bank less adjusted book) | B13: =(B9-B12) -> 0

Sheet Subledgers
A1: Saltbrush Beverage Co., December 2025 Close
A2: Subledgers
A3: (whole dollars, except the Statements sheet, which is $ in thousands) Accounts receivable aging and accounts payable, December 31, 2025
B5: Amount
A6: Accounts receivable aging
A7: Current | B7: =('Adjusted TB'!F7*0.6) -> 4609905.9
A8: 1 to 30 days | B8: =('Adjusted TB'!F7*0.25) -> 1920794.1
A9: 31 to 60 days | B9: =('Adjusted TB'!F7*0.08) -> 614654.11
A10: 61 to 90 days | B10: =('Adjusted TB'!F7*0.04) -> 307327.06
A11: Over 90 days | B11: =('Adjusted TB'!F7-(B7+B8+B9+B10)) -> 230495.29
A12: Total accounts receivable, gross | B12: =(B7+B8+B9+B10+B11) -> 7683176.4
A14: Allowance for doubtful accounts (loss rate by aging bucket)
A15: Current: loss rate 0.3% | B15: =(B7*0.003) -> 13829.718
A16: 1 to 30 days: loss rate 1.0% | B16: =(B8*0.01) -> 19207.941
A17: 31 to 60 days: loss rate 4.0% | B17: =(B9*0.04) -> 24586.165
A18: 61 to 90 days: loss rate 12.0% | B18: =(B10*0.12) -> 36879.247
A19: Over 90 days: loss rate 35% | B19: =(B11*0.35) -> 80673.352
A20: Computed allowance for doubtful accounts | B20: =(B15+B16+B17+B18+B19) -> 175176.42
A22: Less: allowance for doubtful accounts | B22: ='Adjusted TB'!G8 -> 175176.42
A23: Accounts receivable, net | B23: =(B12-B22) -> 7508000
A24: Check: AR aging ties to the AR control account | B24: =(B23-7508000) -> 0
A25: Check: computed allowance equals the allowance on the adjusted TB | B25: =(B20-B22) -> 3.4924597e-10
A27: Accounts payable
A28: Can and packaging supplier | B28: =1850000 -> 1850000
A29: Ingredient supplier | B29: =1240000 -> 1240000
A30: Freight and logistics carrier | B30: =980000 -> 980000
A31: Contract packing partner | B31: =875000 -> 875000
A32: Other trade payables | B32: =('Adjusted TB'!G14-(B28+B29+B30+B31)) -> 789000
A33: Total accounts payable, per subledger | B33: =(B28+B29+B30+B31+B32) -> 5734000
A34: Check: AP subledger ties to the AP control account | B34: =(B33-'Adjusted TB'!G14) -> 0

Sheet Adjusted TB
A1: Saltbrush Beverage Co., December 2025 Close
A2: Adjusted Trial Balance
A3: (whole dollars, except the Statements sheet, which is $ in thousands) December 31, 2025
B5: Unadjusted Debit | C5: Unadjusted Credit | D5: Adjustments Debit | E5: Adjustments Credit | F5: Adjusted Debit | G5: Adjusted Credit
A6: Cash | B6: ='Unadjusted TB'!B6 -> 2529245 | C6: ='Unadjusted TB'!C6 -> 0 | D6: =0 -> 0 | E6: =('Adjusting Entries'!E34) -> 245 | F6: =((B6+D6)-E6) -> 2529000 | G6: =0 -> 0
A7: Accounts receivable, gross | B7: ='Unadjusted TB'!B7 -> 7683176.4 | C7: ='Unadjusted TB'!C7 -> 0 | D7: =0 -> 0 | E7: =0 -> 0 | F7: =((B7+D7)-E7) -> 7683176.4 | G7: =0 -> 0
A8: Allowance for doubtful accounts | B8: ='Unadjusted TB'!B8 -> 0 | C8: ='Unadjusted TB'!C8 -> 153176.42 | D8: =0 -> 0 | E8: =('Adjusting Entries'!E40) -> 22000 | F8: =0 -> 0 | G8: =((C8+E8)-D8) -> 175176.42
A9: Inventory | B9: ='Unadjusted TB'!B9 -> 6843000 | C9: ='Unadjusted TB'!C9 -> 0 | D9: =('Adjusting Entries'!D45) -> 215000 | E9: =('Adjusting Entries'!E28) -> 50000 | F9: =((B9+D9)-E9) -> 7008000 | G9: =0 -> 0
A10: Prepaid expenses | B10: ='Unadjusted TB'!B10 -> 786000 | C10: ='Unadjusted TB'!C10 -> 0 | D10: =0 -> 0 | E10: =('Adjusting Entries'!E22) -> 65000 | F10: =((B10+D10)-E10) -> 721000 | G10: =0 -> 0
A11: Production variance clearing | B11: ='Unadjusted TB'!B11 -> 190333.33 | C11: ='Unadjusted TB'!C11 -> 0 | D11: =0 -> 0 | E11: =('Adjusting Entries'!E31) -> 190333.33 | F11: =((B11+D11)-E11) -> 0 | G11: =0 -> 0
A12: Property, plant and equipment, gross | B12: ='Unadjusted TB'!B12 -> 40300000 | C12: ='Unadjusted TB'!C12 -> 0 | D12: =0 -> 0 | E12: =0 -> 0 | F12: =((B12+D12)-E12) -> 40300000 | G12: =0 -> 0
A13: Accumulated depreciation | B13: ='Unadjusted TB'!B13 -> 0 | C13: ='Unadjusted TB'!C13 -> 19817250 | D13: =0 -> 0 | E13: =('Adjusting Entries'!E25) -> 167750 | F13: =0 -> 0 | G13: =((C13+E13)-D13) -> 19985000
A14: Accounts payable | B14: ='Unadjusted TB'!B14 -> 0 | C14: ='Unadjusted TB'!C14 -> 5519000 | D14: =0 -> 0 | E14: =('Adjusting Entries'!E46) -> 215000 | F14: =0 -> 0 | G14: =((C14+E14)-D14) -> 5734000
A15: Accrued payroll | B15: ='Unadjusted TB'!B15 -> 0 | C15: ='Unadjusted TB'!C15 -> 0 | D15: =0 -> 0 | E15: =('Adjusting Entries'!E9) -> 130714.29 | F15: =0 -> 0 | G15: =((C15+E15)-D15) -> 130714.29
A16: Accrued payroll taxes | B16: ='Unadjusted TB'!B16 -> 0 | C16: ='Unadjusted TB'!C16 -> 0 | D16: =0 -> 0 | E16: =('Adjusting Entries'!E13) -> 9999.6429 | F16: =0 -> 0 | G16: =((C16+E16)-D16) -> 9999.6429
A17: Accrued freight | B17: ='Unadjusted TB'!B17 -> 0 | C17: ='Unadjusted TB'!C17 -> 0 | D17: =0 -> 0 | E17: =('Adjusting Entries'!E16) -> 300000 | F17: =0 -> 0 | G17: =((C17+E17)-D17) -> 300000
A18: Accrued utilities | B18: ='Unadjusted TB'!B18 -> 0 | C18: ='Unadjusted TB'!C18 -> 0 | D18: =0 -> 0 | E18: =('Adjusting Entries'!E19) -> 129000 | F18: =0 -> 0 | G18: =((C18+E18)-D18) -> 129000
A19: Accrued interest | B19: ='Unadjusted TB'!B19 -> 0 | C19: ='Unadjusted TB'!C19 -> 0 | D19: =0 -> 0 | E19: =('Adjusting Entries'!E37) -> 25312.5 | F19: =0 -> 0 | G19: =((C19+E19)-D19) -> 25312.5
A20: Income tax payable | B20: ='Unadjusted TB'!B20 -> 0 | C20: ='Unadjusted TB'!C20 -> 400000 | D20: =('Adjusting Entries'!D43) -> 297526.6 | E20: =0 -> 0 | F20: =0 -> 0 | G20: =((C20+E20)-D20) -> 102473.4
A21: Accrued bonus (annual pool) | B21: ='Unadjusted TB'!B21 -> 0 | C21: ='Unadjusted TB'!C21 -> 1100000 | D21: =0 -> 0 | E21: =('Adjusting Entries'!E49) -> 100000 | F21: =0 -> 0 | G21: =((C21+E21)-D21) -> 1200000
A22: Accrued vacation | B22: ='Unadjusted TB'!B22 -> 0 | C22: ='Unadjusted TB'!C22 -> 600000 | D22: =0 -> 0 | E22: =0 -> 0 | F22: =0 -> 0 | G22: =((C22+E22)-D22) -> 600000
A23: Other accrued expenses | B23: ='Unadjusted TB'!B23 -> 0 | C23: ='Unadjusted TB'!C23 -> 387500.17 | D23: =0 -> 0 | E23: =0 -> 0 | F23: =0 -> 0 | G23: =((C23+E23)-D23) -> 387500.17
A24: Revolver | B24: ='Unadjusted TB'!B24 -> 0 | C24: ='Unadjusted TB'!C24 -> 0 | D24: =0 -> 0 | E24: =0 -> 0 | F24: =0 -> 0 | G24: =((C24+E24)-D24) -> 0
A25: Equipment loan | B25: ='Unadjusted TB'!B25 -> 0 | C25: ='Unadjusted TB'!C25 -> 4500000 | D25: =0 -> 0 | E25: =0 -> 0 | F25: =0 -> 0 | G25: =((C25+E25)-D25) -> 4500000
A26: Common stock and paid in capital | B26: ='Unadjusted TB'!B26 -> 0 | C26: ='Unadjusted TB'!C26 -> 6000000 | D26: =0 -> 0 | E26: =0 -> 0 | F26: =0 -> 0 | G26: =((C26+E26)-D26) -> 6000000
A27: Retained earnings, beginning of year | B27: ='Unadjusted TB'!B27 -> 0 | C27: ='Unadjusted TB'!C27 -> 15368000 | D27: =0 -> 0 | E27: =0 -> 0 | F27: =0 -> 0 | G27: =((C27+E27)-D27) -> 15368000
A28: Revenue | B28: ='Unadjusted TB'!B28 -> 0 | C28: ='Unadjusted TB'!C28 -> 72116000 | D28: =0 -> 0 | E28: =0 -> 0 | F28: =0 -> 0 | G28: =((C28+E28)-D28) -> 72116000
A29: Cost of sales at standard | B29: ='Unadjusted TB'!B29 -> 44073615 | C29: ='Unadjusted TB'!C29 -> 0 | D29: =('Adjusting Entries'!D7+'Adjusting Entries'!D11+'Adjusting Entries'!D27) -> 149384.98 | E29: =0 -> 0 | F29: =((B29+D29)-E29) -> 44223000 | G29: =0 -> 0
A30: Manufacturing variances | B30: ='Unadjusted TB'!B30 -> 2093666.7 | C30: ='Unadjusted TB'!C30 -> 0 | D30: =('Adjusting Entries'!D30) -> 190333.33 | E30: =0 -> 0 | F30: =((B30+D30)-E30) -> 2284000 | G30: =0 -> 0
A31: Selling and distribution | B31: ='Unadjusted TB'!B31 -> 8354000 | C31: ='Unadjusted TB'!C31 -> 0 | D31: =('Adjusting Entries'!D15) -> 300000 | E31: =0 -> 0 | F31: =((B31+D31)-E31) -> 8654000 | G31: =0 -> 0
A32: Marketing | B32: ='Unadjusted TB'!B32 -> 4688000 | C32: ='Unadjusted TB'!C32 -> 0 | D32: =0 -> 0 | E32: =0 -> 0 | F32: =((B32+D32)-E32) -> 4688000 | G32: =0 -> 0
A33: General and administrative | B33: ='Unadjusted TB'!B33 -> 4690426.1 | C33: ='Unadjusted TB'!C33 -> 0 | D33: =('Adjusting Entries'!D8+'Adjusting Entries'!D12+'Adjusting Entries'!D18+'Adjusting Entries'!D21+'Adjusting Entries'!D33+'Adjusting Entries'!D39+'Adjusting Entries'!D48) -> 357573.94 | E33: =0 -> 0 | F33: =((B33+D33)-E33) -> 5048000 | G33: =0 -> 0
A34: Depreciation | B34: ='Unadjusted TB'!B34 -> 1845250 | C34: ='Unadjusted TB'!C34 -> 0 | D34: =('Adjusting Entries'!D24) -> 167750 | E34: =0 -> 0 | F34: =((B34+D34)-E34) -> 2013000 | G34: =0 -> 0
A35: Interest expense | B35: ='Unadjusted TB'!B35 -> 388687.5 | C35: ='Unadjusted TB'!C35 -> 0 | D35: =('Adjusting Entries'!D36) -> 25312.5 | E35: =0 -> 0 | F35: =((B35+D35)-E35) -> 414000 | G35: =0 -> 0
A36: Income tax expense | B36: ='Unadjusted TB'!B36 -> 1495526.6 | C36: ='Unadjusted TB'!C36 -> 0 | D36: =0 -> 0 | E36: =('Adjusting Entries'!E42) -> 297526.6 | F36: =((B36+D36)-E36) -> 1198000 | G36: =0 -> 0
A37: Total | B37: =(B6+B7+B8+B9+B10+B11+B12+B13+B14+B15+B16+B17+B18+B19+B20+B21+B22+B23+B24+B25+B26+B27+B28+B29+B30+B31+B32+B33+B34+B35+B36) -> 1.2596093e+08 | C37: =(C6+C7+C8+C9+C10+C11+C12+C13+C14+C15+C16+C17+C18+C19+C20+C21+C22+C23+C24+C25+C26+C27+C28+C29+C30+C31+C32+C33+C34+C35+C36) -> 1.2596093e+08 | D37: =(D6+D7+D8+D9+D10+D11+D12+D13+D14+D15+D16+D17+D18+D19+D20+D21+D22+D23+D24+D25+D26+D27+D28+D29+D30+D31+D32+D33+D34+D35+D36) -> 1702881.4 | E37: =(E6+E7+E8+E9+E10+E11+E12+E13+E14+E15+E16+E17+E18+E19+E20+E21+E22+E23+E24+E25+E26+E27+E28+E29+E30+E31+E32+E33+E34+E35+E36) -> 1702881.4 | F37: =(F6+F7+F8+F9+F10+F11+F12+F13+F14+F15+F16+F17+F18+F19+F20+F21+F22+F23+F24+F25+F26+F27+F28+F29+F30+F31+F32+F33+F34+F35+F36) -> 1.2676318e+08 | G37: =(G6+G7+G8+G9+G10+G11+G12+G13+G14+G15+G16+G17+G18+G19+G20+G21+G22+G23+G24+G25+G26+G27+G28+G29+G30+G31+G32+G33+G34+G35+G36) -> 1.2676318e+08
A39: Net income, unadjusted (revenue less unadjusted expense accounts) | B39: =(C28-(B29+B30+B31+B32+B33+B34+B35+B36)) -> 4486828.2
A40: Net income, adjusted (revenue less adjusted expense accounts) | B40: =(G28-(F29+F30+F31+F32+F33+F34+F35+F36)) -> 3594000
A41: Net income effect of the adjusting entries | B41: =(B40-B39) -> -892828.16
A42: Income tax rate used for the December provision (the model's own effective FY2025 rate) | B42: =0.2499478406 -> 0.24994784

Sheet Statements
A1: Saltbrush Beverage Co., December 2025 Close
A2: FY2025 Statements, from the adjusted trial balance
A3: ($ in thousands, with a whole dollar section below for the data file)
B5: FY2025
A6: Income Statement, for the year ended December 31, 2025 ($ in thousands)
A7: Revenue | B7: =('Adjusted TB'!G28/1000) -> 72116
A8: Cost of sales at standard | B8: =('Adjusted TB'!F29/1000) -> 44223
A9: Manufacturing variances | B9: =('Adjusted TB'!F30/1000) -> 2284
A10: Gross profit | B10: =((B7-B8)-B9) -> 25609
A11: Selling and distribution | B11: =('Adjusted TB'!F31/1000) -> 8654
A12: Marketing | B12: =('Adjusted TB'!F32/1000) -> 4688
A13: General and administrative | B13: =('Adjusted TB'!F33/1000) -> 5048
A14: EBITDA | B14: =(((B10-B11)-B12)-B13) -> 7219
A15: Depreciation | B15: =('Adjusted TB'!F34/1000) -> 2013
A16: Operating income | B16: =(B14-B15) -> 5206
A17: Interest expense | B17: =('Adjusted TB'!F35/1000) -> 414
A18: Income before taxes | B18: =(B16-B17) -> 4792
A19: Income tax expense | B19: =('Adjusted TB'!F36/1000) -> 1198
A20: Net income | B20: =(B18-B19) -> 3594
A22: Balance Sheet, as of December 31, 2025 ($ in thousands)
A23: Cash and cash equivalents | B23: =('Adjusted TB'!F6/1000) -> 2529
A24: Accounts receivable | B24: =(('Adjusted TB'!F7-'Adjusted TB'!G8)/1000) -> 7508
A25: Inventory | B25: =('Adjusted TB'!F9/1000) -> 7008
A26: Prepaid expenses | B26: =('Adjusted TB'!F10/1000) -> 721
A27: Total current assets | B27: =(B23+B24+B25+B26) -> 17766
A28: Property, plant and equipment, net | B28: =(('Adjusted TB'!F12-'Adjusted TB'!G13)/1000) -> 20315
A29: Total assets | B29: =(B27+B28) -> 38081
A30: Accounts payable | B30: =('Adjusted TB'!G14/1000) -> 5734
A31: Accrued liabilities | B31: =(('Adjusted TB'!G15+'Adjusted TB'!G16+'Adjusted TB'!G17+'Adjusted TB'!G18+'Adjusted TB'!G19+'Adjusted TB'!G20+'Adjusted TB'!G21+'Adjusted TB'!G22+'Adjusted TB'!G23)/1000) -> 2885
A32: Total current liabilities | B32: =(B30+B31) -> 8619
A33: Revolver | B33: =('Adjusted TB'!G24/1000) -> 0
A34: Equipment loan | B34: =('Adjusted TB'!G25/1000) -> 4500
A35: Total liabilities | B35: =((B32+B33)+B34) -> 13119
A36: Common stock and paid in capital | B36: =('Adjusted TB'!G26/1000) -> 6000
A37: Retained earnings | B37: =(('Adjusted TB'!G27/1000)+B20) -> 18962
A38: Total equity | B38: =(B36+B37) -> 24962
A39: Total liabilities and equity | B39: =(B35+B38) -> 38081
A41: Income Statement, for the year ended December 31, 2025 (whole dollars, supports the data file)
A42: Revenue | B42: =('Adjusted TB'!G28/1) -> 72116000
A43: Cost of sales at standard | B43: =('Adjusted TB'!F29/1) -> 44223000
...

Sheet Checks
A1: Checks
A3: Overall status | B3: =IF(COUNTIF(C5:C49,"CHECK")=0,"ALL OK","CHECK FAILURES") -> ALL OK
A4: Check | B4: Difference | C4: Status
A5: Unadjusted TB balances (debits equal credits) | B5: =('Unadjusted TB'!B37)-('Unadjusted TB'!C37) -> 0 | C5: =IF(ABS(B5)<0.5,"OK","CHECK") -> OK
A6: Adjusting entries balance (debits equal credits) | B6: =('Adjusting Entries'!D50)-('Adjusting Entries'!E50) -> 0 | C6: =IF(ABS(B6)<0.5,"OK","CHECK") -> OK
A7: Adjusted TB, unadjusted column balances | B7: =('Adjusted TB'!B37)-('Adjusted TB'!C37) -> 0 | C7: =IF(ABS(B7)<0.5,"OK","CHECK") -> OK
A8: Adjusted TB, adjustments column balances | B8: =('Adjusted TB'!D37)-('Adjusted TB'!E37) -> 0 | C8: =IF(ABS(B8)<0.5,"OK","CHECK") -> OK
A9: Adjusted TB balances (debits equal credits) | B9: =('Adjusted TB'!F37)-('Adjusted TB'!G37) -> 0 | C9: =IF(ABS(B9)<0.5,"OK","CHECK") -> OK
A10: Inventory: adjusted inventory equals the physical count | B10: =('Inventory'!B12)-(0) -> 0 | C10: =IF(ABS(B10)<0.5,"OK","CHECK") -> OK
A11: Inventory: December's variance close out plus the year to date balance equals the FY2025 total | B11: =('Inventory'!B18)-(0) -> 0 | C11: =IF(ABS(B11)<0.5,"OK","CHECK") -> OK
A12: Bank reconciliation: adjusted bank equals adjusted book | B12: =('Bank Reconciliation'!B13)-(0) -> 0 | C12: =IF(ABS(B12)<0.5,"OK","CHECK") -> OK
A13: Accruals and prepaids: accrued liabilities schedule ties to the adjusted TB | B13: =('Accruals and Prepaids'!B16)-(0) -> 0 | C13: =IF(ABS(B13)<0.5,"OK","CHECK") -> OK
A14: Accruals and prepaids: prepaid amortization ties to the adjusted TB | B14: =('Accruals and Prepaids'!D22)-(0) -> 0 | C14: =IF(ABS(B14)<0.5,"OK","CHECK") -> OK
A15: Fixed assets: net PP&E ties to the adjusted TB | B15: =('Fixed Assets'!B11)-(0) -> 0 | C15: =IF(ABS(B15)<0.5,"OK","CHECK") -> OK
A16: Subledgers: AR aging ties to the AR control account | B16: =('Subledgers'!B24)-(0) -> 0 | C16: =IF(ABS(B16)<0.5,"OK","CHECK") -> OK
A17: Subledgers: computed allowance (aging buckets by loss rate) ties to the adjusted TB | B17: =('Subledgers'!B25)-(0) -> 3.4924597e-10 | C17: =IF(ABS(B17)<0.5,"OK","CHECK") -> OK
A18: Subledgers: AP subledger ties to the AP control account | B18: =('Subledgers'!B34)-(0) -> 0 | C18: =IF(ABS(B18)<0.5,"OK","CHECK") -> OK
A19: Statements: balance sheet balances | B19: =('Statements'!B29)-('Statements'!B39) -> 0 | C19: =IF(ABS(B19)<0.5,"OK","CHECK") -> OK
A20: Statements: whole dollar balance sheet balances | B20: =('Statements'!B64)-('Statements'!B74) -> 0 | C20: =IF(ABS(B20)<0.5,"OK","CHECK") -> OK
A21: Adjusted TB ties to the Saltbrush FY2025 model: cash | B21: =('Statements'!B23)-(2529) -> 0 | C21: =IF(ABS(B21)<0.5,"OK","CHECK") -> OK
A22: Adjusted TB ties to the Saltbrush FY2025 model: accounts receivable | B22: =('Statements'!B24)-(7508) -> 0 | C22: =IF(ABS(B22)<0.5,"OK","CHECK") -> OK
A23: Adjusted TB ties to the Saltbrush FY2025 model: inventory | B23: =('Statements'!B25)-(7008) -> 0 | C23: =IF(ABS(B23)<0.5,"OK","CHECK") -> OK
A24: Adjusted TB ties to the Saltbrush FY2025 model: prepaid expenses | B24: =('Statements'!B26)-(721) -> 0 | C24: =IF(ABS(B24)<0.5,"OK","CHECK") -> OK
A25: Adjusted TB ties to the Saltbrush FY2025 model: PP&E net | B25: =('Statements'!B28)-(20315) -> 0 | C25: =IF(ABS(B25)<0.5,"OK","CHECK") -> OK
A26: Adjusted TB ties to the Saltbrush FY2025 model: accounts payable | B26: =('Statements'!B30)-(5734) -> 0 | C26: =IF(ABS(B26)<0.5,"OK","CHECK") -> OK
A27: Adjusted TB ties to the Saltbrush FY2025 model: accrued liabilities | B27: =('Statements'!B31)-(2885) -> 0 | C27: =IF(ABS(B27)<0.5,"OK","CHECK") -> OK
A28: Adjusted TB ties to the Saltbrush FY2025 model: equipment loan | B28: =('Statements'!B34)-(4500) -> 0 | C28: =IF(ABS(B28)<0.5,"OK","CHECK") -> OK
A29: Adjusted TB ties to the Saltbrush FY2025 model: revenue | B29: =('Statements'!B7)-(72116) -> 0 | C29: =IF(ABS(B29)<0.5,"OK","CHECK") -> OK
A30: Adjusted TB ties to the Saltbrush FY2025 model: depreciation | B30: =('Statements'!B15)-(2013) -> 0 | C30: =IF(ABS(B30)<0.5,"OK","CHECK") -> OK
A31: Adjusted TB ties to the Saltbrush FY2025 model: interest expense | B31: =('Statements'!B17)-(414) -> 0 | C31: =IF(ABS(B31)<0.5,"OK","CHECK") -> OK
A32: Adjusted TB ties to the Saltbrush FY2025 model: income tax expense | B32: =('Statements'!B19)-(1198) -> 0 | C32: =IF(ABS(B32)<0.5,"OK","CHECK") -> OK
A33: Adjusted TB ties to the Saltbrush FY2025 model: net income | B33: =('Statements'!B20)-(3594) -> 0 | C33: =IF(ABS(B33)<0.5,"OK","CHECK") -> OK
A34: Adjusted TB ties to the Saltbrush FY2025 model: retained earnings, ending | B34: =('Statements'!B37)-(18962) -> 0 | C34: =IF(ABS(B34)<0.5,"OK","CHECK") -> OK
A35: Adjusted TB ties to the Saltbrush FY2025 model: manufacturing variances | B35: =('Statements'!B9)-(2284) -> 0 | C35: =IF(ABS(B35)<0.5,"OK","CHECK") -> OK
A36: JE 01 balances (debits equal credits) | B36: =((D7+D8+D9))-((E7+E8+E9)) -> 0 | C36: =IF(ABS(B36)<0.5,"OK","CHECK") -> OK
A37: JE 02 balances (debits equal credits) | B37: =((D11+D12+D13))-((E11+E12+E13)) -> 0 | C37: =IF(ABS(B37)<0.5,"OK","CHECK") -> OK
A38: JE 03 balances (debits equal credits) | B38: =((D15+D16))-((E15+E16)) -> 0 | C38: =IF(ABS(B38)<0.5,"OK","CHECK") -> OK
A39: JE 04 balances (debits equal credits) | B39: =((D18+D19))-((E18+E19)) -> 0 | C39: =IF(ABS(B39)<0.5,"OK","CHECK") -> OK
A40: JE 05 balances (debits equal credits) | B40: =((D21+D22))-((E21+E22)) -> 0 | C40: =IF(ABS(B40)<0.5,"OK","CHECK") -> OK
A41: JE 06 balances (debits equal credits) | B41: =((D24+D25))-((E24+E25)) -> 0 | C41: =IF(ABS(B41)<0.5,"OK","CHECK") -> OK
...
