Workbook

Sheet Cover
A1: Escentials LLC
A2: Financial Statements and FP&A Pack
A3: Fiscal year ended December 31, 2025 · USD · unaudited
A5: Illustrative figures for privacy. They are modeled on the business's size, sales channels and products, and are not its actual results.
A7: Model status | B7: =IF('Checks'!$B$22=0,"All 15 integrity checks pass","Check errors: "&'Checks'!$B$22&" failing") -> All 15 integrity checks pass
A9: Contents
A10: Income Statement | B10: Statement of operations for 2025
A11: Balance Sheet | B11: Financial position at December 31, 2025, with the January 1 opening balance
A12: Cash Flows | B12: Statement of cash flows, indirect method
A13: Equity Statement | B13: Statement of changes in members' equity
A14: Notes | B14: Accounting policies and supporting detail
A15: Budget vs Actual | B15: ="Spending against the "&TEXT('Assumptions'!$B$25,"$#,##0")&" monthly budget, by line and by month" -> Spending against the $20,000 monthly budget, by line and by month
A16: Forecast | B16: FY2026 monthly forecast with Base, Upside and Downside scenarios
A17: KPIs | B17: Monthly KPIs with four charts
A18: SQL Analysis | B18: Results of the analysis queries in 5_SQLite_Database/queries/, with charts
A19: Monthly P&L | B19: Income statement by month
A20: Monthly BS | B20: Balance sheet at the opening and every month end
A21: Monthly CF | B21: Cash flow by month
A22: Schedules | B22: Roll forwards: equipment, inventory, receivables, payables, sales tax, equity
A23: Budget | B23: The monthly budget by line
A24: Assumptions | B24: Every input in one place
A25: Data | B25: The monthly SQL pull that feeds the model
A26: Checks | B26: Integrity checks: every one must read OK
A28: Color code
A29: 1000 | B29: Blue: an input, or data pulled from the database with SQL
A30: =500*2 -> 1000 | B30: Black: a formula working within its own sheet
A31: ='Assumptions'!$B$25 -> 20000 | B31: Green: a formula linking to another sheet (this one pulls the monthly budget from Assumptions)
A32: 1000 | B32: Yellow fill: a key assumption, the place to change the model
A34: How it is built
A35: Data | B35: Transactions sit in a SQLite database, 5_SQLite_Database/escentials.db: orders, order lines, refunds, expenses and owner transactions.
A36: SQL | B36: Queries in 5_SQLite_Database/queries/ summarize them by month, and the results land on the Data sheet.
A37: Model | B37: Every statement is a live formula that traces back to the Data sheet, so changing an input updates the whole pack.
A38: Checks | B38: The Checks sheet proves it ties: the balance sheet balances every month, cash flow agrees with the balance sheet, and sales agree with SQL control totals.
A39: Tools | B39: Excel, SQL (SQLite), Tableau and PowerPoint.
A41: Prepared by | B41: George Murad

Sheet Income Statement
A1: Escentials LLC
A2: Statement of Operations
A3: For the year ended December 31, 2025
A4: Unaudited. Illustrative figures for privacy: modeled on the business's size, channels and products, not its actual results.
A6: USD | C6: 2025 | D6: % of net revenue
A7: Revenue
A8: Merchandise sales | C8: ='Monthly P&L'!O6+'Monthly P&L'!O7 -> 200955.62 | D8: =IFERROR(C8/C$11,0) -> 0.99122718
A9: Shipping income | C9: ='Monthly P&L'!O8 -> 7631.26 | D9: =IFERROR(C9/C$11,0) -> 0.037641706
A10: Less: discounts, returns and refunds | C10: ='Monthly P&L'!O9+'Monthly P&L'!O10 -> -5852.71 | D10: =IFERROR(C10/C$11,0) -> -0.028868888
A11: Net revenue | C11: =SUM(C8:C10) -> 202734.17 | D11: =IFERROR(C11/C$11,0) -> 1
A12: Cost of goods sold | C12: ='Monthly P&L'!O16 -> 140408.25 | D12: =IFERROR(C12/C$11,0) -> 0.69257319
A13: Gross profit | C13: =C11-C12 -> 62325.92 | D13: =IFERROR(C13/C$11,0) -> 0.30742681
A15: Operating expenses
A16: Marketplace fees | C16: ='Monthly P&L'!O22 -> 15851.1 | D16: =IFERROR(C16/C$11,0) -> 0.078186622
A17: Payment processing | C17: ='Monthly P&L'!O23 -> 3223.94 | D17: =IFERROR(C17/C$11,0) -> 0.015902302
A18: Shipping and fulfillment | C18: ='Monthly P&L'!O24 -> 17934.9 | D18: =IFERROR(C18/C$11,0) -> 0.088465107
A19: Advertising and marketing | C19: ='Monthly P&L'!O25 -> 6754.06 | D19: =IFERROR(C19/C$11,0) -> 0.033314858
A20: Packaging and supplies | C20: ='Monthly P&L'!O26 -> 1036.1 | D20: =IFERROR(C20/C$11,0) -> 0.0051106333
A21: Software and subscriptions | C21: ='Monthly P&L'!O27 -> 924.4 | D21: =IFERROR(C21/C$11,0) -> 0.0045596655
A22: Professional fees | C22: ='Monthly P&L'!O28 -> 970 | D22: =IFERROR(C22/C$11,0) -> 0.0047845906
A23: Taxes and licenses | C23: ='Monthly P&L'!O29 -> 910 | D23: =IFERROR(C23/C$11,0) -> 0.0044886365
A24: General and administrative | C24: ='Monthly P&L'!O30 -> 1003.27 | D24: =IFERROR(C24/C$11,0) -> 0.0049486971
A25: Depreciation | C25: ='Monthly P&L'!O31 -> 503.25 | D25: =IFERROR(C25/C$11,0) -> 0.0024823146
A26: Total operating expenses | C26: =SUM(C16:C25) -> 49111.02 | D26: =IFERROR(C26/C$11,0) -> 0.24224343
A28: Operating income | C28: =C13-C26 -> 13214.9 | D28: =IFERROR(C28/C$11,0) -> 0.065183388
A30: Net income | C30: =C28 -> 13214.9 | D30: =IFERROR(C30/C$11,0) -> 0.065183388
A32: No income tax is recorded: the LLC is taxed as a pass through entity (Note 7).
A33: See the accompanying notes.

Sheet Balance Sheet
A1: Escentials LLC
A2: Balance Sheet
A3: December 31, 2025, with the opening balance at January 1, 2025
A4: Unaudited. Illustrative figures for privacy: modeled on the business's size, channels and products, not its actual results.
A6: USD | C6: Dec 31, 2025 | D6: Jan 1, 2025
A7: Assets
A8: Current assets
A9: Cash | C9: ='Monthly BS'!N6 -> 13286.169 | D9: ='Monthly BS'!B6 -> 9000
A10: Accounts receivable | C10: ='Monthly BS'!N7 -> 2595.5458 | D10: ='Monthly BS'!B7 -> 2374
A11: Inventory | C11: ='Monthly BS'!N8 -> 2197.75 | D11: ='Monthly BS'!B8 -> 700
A12: Total current assets | C12: =SUM(C9:C11) -> 18079.465 | D12: =SUM(D9:D11) -> 12074
A13: Equipment, net of accumulated depreciation | C13: ='Monthly BS'!N10 -> 1143.75 | D13: ='Monthly BS'!B10 -> 0
A14: Total assets | C14: =C12+C13 -> 19223.215 | D14: =D12+D13 -> 12074
A16: Liabilities and members' equity
A17: Current liabilities
A18: Accounts payable | C18: ='Monthly BS'!N14 -> 8374.3548 | D18: ='Monthly BS'!B14 -> 8019
A19: Sales tax payable | C19: ='Monthly BS'!N15 -> 786.96 | D19: ='Monthly BS'!B15 -> 708
A20: Total liabilities | C20: =C18+C19 -> 9161.3148 | D20: =D18+D19 -> 8727
A21: Members' equity | C21: ='Monthly BS'!N17 -> 10061.9 | D21: ='Monthly BS'!B17 -> 3347
A22: Total liabilities and members' equity | C22: =C20+C21 -> 19223.215 | D22: =D20+D21 -> 12074
A24: See the accompanying notes.

Sheet Cash Flows
A1: Escentials LLC
A2: Statement of Cash Flows
A3: For the year ended December 31, 2025 (indirect method)
A4: Unaudited. Illustrative figures for privacy: modeled on the business's size, channels and products, not its actual results.
A6: USD | C6: 2025
A7: Cash flows from operating activities
A8: Net income | C8: ='Monthly CF'!O6 -> 13214.9
A9: Adjustments to reconcile net income to net cash from operating activities:
A10: Depreciation | C10: ='Monthly CF'!O7 -> 503.25
A11: Changes in operating assets and liabilities:
A12: Accounts receivable | C12: ='Monthly CF'!O9 -> -221.54581
A13: Inventory | C13: ='Monthly CF'!O10 -> -1497.75
A14: Accounts payable | C14: ='Monthly CF'!O11 -> 355.35484
A15: Sales tax payable | C15: ='Monthly CF'!O12 -> 78.96
A16: Net cash from operating activities | C16: =SUM(C8:C15) -> 12433.169
A18: Cash flows from investing activities
A19: Purchases of equipment | C19: ='Monthly CF'!O16 -> -1647
A20: Net cash used in investing activities | C20: =C19 -> -1647
A22: Cash flows from financing activities
A23: Member contributions | C23: ='Monthly CF'!O20 -> 2500
A24: Member distributions | C24: ='Monthly CF'!O21 -> -9000
A25: Net cash from financing activities | C25: =C23+C24 -> -6500
A27: Net change in cash | C27: =C16+C20+C25 -> 4286.169
A28: Cash, beginning of year | C28: ='Monthly CF'!O25 -> 9000
A29: Cash, end of year | C29: =C28+C27 -> 13286.169
A31: See the accompanying notes.

Sheet Equity Statement
A1: Escentials LLC
A2: Statement of Changes in Members' Equity
A3: For the year ended December 31, 2025
A4: Unaudited. Illustrative figures for privacy: modeled on the business's size, channels and products, not its actual results.
A6: USD | C6: Members' equity
A7: Balance, January 1, 2025 | C7: ='Schedules'!B35 -> 3347
A8: Member contributions | C8: ='Schedules'!O32 -> 2500
A9: Net income | C9: ='Income Statement'!C30 -> 13214.9
A10: Member distributions | C10: ='Schedules'!O34 -> -9000
A11: Balance, December 31, 2025 | C11: =SUM(C7:C10) -> 10061.9
A13: See the accompanying notes.

Sheet Notes
A1: Escentials LLC
A2: Notes to the Financial Statements
A3: For the year ended December 31, 2025
A4: Unaudited. Illustrative figures for privacy: modeled on the business's size, channels and products, not its actual results.
A6: 1. Organization and nature of business
A7: Escentials LLC (the Company) is a limited liability company. It sells authentic designer fragrance online through eBay and its own Shopify store, and sells its own Car Perfume line: hanging glass bottles and refills.
A9: 2. Basis of presentation
A10: These statements are prepared on the accrual basis under accounting principles generally accepted in the United States (US GAAP). They are unaudited and prepared by management. The figures are illustrative: they are modeled on the Company's size, sales channels and products, and are not its actual results, which are kept private.
A12: 3. Use of estimates
A13: Preparing financial statements requires estimates, including returns, the value of inventory and the useful life of equipment. Actual results could differ.
A15: 4. Revenue recognition
A16: Revenue is recognized under ASC 606 when control of a product passes to the customer, at shipment, and is reported net of discounts and refunds. For drop shipped designer fragrance the Company is the principal: it sets the price, accepts the order and handles returns, so it reports those sales gross and the supplier's charge as cost of goods sold. Shipping charged to customers is revenue; shipping and handling costs are fulfillment costs within operating expenses. Sales tax collected on Shopify orders is a liability, not revenue; eBay collects and remits the tax on eBay orders as the marketplace facilitator.
A18: 5. Inventory
A19: ="Inventory is Car Perfume bottles, fragrance oil and refills, stated at the lower of cost (first in, first out) and net realizable value. "&"Designer fragrance ships directly from the supplier, so the Company holds none of it. Inventory at December 31, 2025 was "&TEXT('Balance Sheet'!C11,"$#,##0")&"." -> Inventory is Car Perfume bottles, fragrance oil and refills, stated at the lower of cost (first in, first out) and net realizable value. Designer fragrance ships directly from the supplier, so the Company holds none of it. Inventory at December 31, 2025 was $2,198.
A21: 6. Equipment
A22: ="Equipment is stated at cost and depreciated on a straight line basis over "&'Assumptions'!$B$22&" years. At December 31, 2025 its cost was "&TEXT('Schedules'!N8,"$#,##0")&", accumulated depreciation was "&TEXT('Schedules'!N11,"$#,##0")&", and 2025 depreciation expense was "&TEXT('Income Statement'!C25,"$#,##0")&"." -> Equipment is stated at cost and depreciated on a straight line basis over 3 years. At December 31, 2025 its cost was $1,647, accumulated depreciation was $503, and 2025 depreciation expense was $503.
A24: 7. Income taxes
A25: The Company is a limited liability company taxed as a pass through entity: its income is reported on its member's tax return, so these statements include no provision for income taxes. The Company pays California's $800 annual LLC tax, included in taxes and licenses.
A27: 8. Advertising
A28: ="Advertising, including eBay promoted listings, is expensed as incurred. It totaled "&TEXT('Income Statement'!C19,"$#,##0")&" in 2025." -> Advertising, including eBay promoted listings, is expensed as incurred. It totaled $6,754 in 2025.
A30: 9. Member transactions
A31: ="During 2025 the member contributed "&TEXT('Schedules'!O32,"$#,##0")&" and received distributions of "&TEXT(-'Schedules'!O34,"$#,##0")&"." -> During 2025 the member contributed $2,500 and received distributions of $9,000.
A33: 10. Concentrations
A34: ="eBay produced "&TEXT('Data'!O6/('Data'!O6+'Data'!O7),"0%")&" of merchandise sales, and Shopify the rest. Designer fragrance comes from a single wholesale supplier; losing it would interrupt sales until a replacement was found." -> eBay produced 58% of merchandise sales, and Shopify the rest. Designer fragrance comes from a single wholesale supplier; losing it would interrupt sales until a replacement was found.
A36: 11. Subsequent events
A37: Subsequent events were evaluated through the date these statements were issued.

Sheet Budget vs Actual
A1: Budget vs Actual
A2: Spending against budget, fiscal 2025. Variance is budget less actual: positive means under budget.
A3: Illustrative figures for privacy: modeled on the business's size, channels and products, not its actual results
A5: By line, full year
A6: Line | B6: Budget | C6: Actual | D6: Variance | E6: Variance % | F6: Status
A7: Designer fragrance COGS | B7: ='Budget'!O6 -> 176400 | C7: ='Monthly P&L'!O14 -> 134006 | D7: =B7-C7 -> 42394 | E7: =IFERROR(D7/B7,0) -> 0.2403288 | F7: =IF(D7>=0,"Favorable","Unfavorable") -> Favorable
A8: Car Perfume and refills COGS | B8: ='Budget'!O7 -> 9600 | C8: ='Monthly P&L'!O15 -> 6402.25 | D8: =B8-C8 -> 3197.75 | E8: =IFERROR(D8/B8,0) -> 0.33309896 | F8: =IF(D8>=0,"Favorable","Unfavorable") -> Favorable
A9: Marketplace fees | B9: ='Budget'!O8 -> 14400 | C9: ='Monthly P&L'!O22 -> 15851.1 | D9: =B9-C9 -> -1451.1 | E9: =IFERROR(D9/B9,0) -> -0.10077083 | F9: =IF(D9>=0,"Favorable","Unfavorable") -> Unfavorable
A10: Payment processing | B10: ='Budget'!O9 -> 3600 | C10: ='Monthly P&L'!O23 -> 3223.94 | D10: =B10-C10 -> 376.06 | E10: =IFERROR(D10/B10,0) -> 0.10446111 | F10: =IF(D10>=0,"Favorable","Unfavorable") -> Favorable
A11: Shipping and fulfillment | B11: ='Budget'!O10 -> 21600 | C11: ='Monthly P&L'!O24 -> 17934.9 | D11: =B11-C11 -> 3665.1 | E11: =IFERROR(D11/B11,0) -> 0.16968056 | F11: =IF(D11>=0,"Favorable","Unfavorable") -> Favorable
A12: Advertising and marketing | B12: ='Budget'!O11 -> 6000 | C12: ='Monthly P&L'!O25 -> 6754.06 | D12: =B12-C12 -> -754.06 | E12: =IFERROR(D12/B12,0) -> -0.12567667 | F12: =IF(D12>=0,"Favorable","Unfavorable") -> Unfavorable
A13: Packaging and supplies | B13: ='Budget'!O12 -> 1200 | C13: ='Monthly P&L'!O26 -> 1036.1 | D13: =B13-C13 -> 163.9 | E13: =IFERROR(D13/B13,0) -> 0.13658333 | F13: =IF(D13>=0,"Favorable","Unfavorable") -> Favorable
A14: Software and subscriptions | B14: ='Budget'!O13 -> 1200 | C14: ='Monthly P&L'!O27 -> 924.4 | D14: =B14-C14 -> 275.6 | E14: =IFERROR(D14/B14,0) -> 0.22966667 | F14: =IF(D14>=0,"Favorable","Unfavorable") -> Favorable
A15: Professional fees | B15: ='Budget'!O14 -> 1200 | C15: ='Monthly P&L'!O28 -> 970 | D15: =B15-C15 -> 230 | E15: =IFERROR(D15/B15,0) -> 0.19166667 | F15: =IF(D15>=0,"Favorable","Unfavorable") -> Favorable
A16: Taxes and licenses | B16: ='Budget'!O15 -> 1200 | C16: ='Monthly P&L'!O29 -> 910 | D16: =B16-C16 -> 290 | E16: =IFERROR(D16/B16,0) -> 0.24166667 | F16: =IF(D16>=0,"Favorable","Unfavorable") -> Favorable
A17: General and administrative | B17: ='Budget'!O16 -> 3600 | C17: ='Monthly P&L'!O30 -> 1003.27 | D17: =B17-C17 -> 2596.73 | E17: =IFERROR(D17/B17,0) -> 0.72131389 | F17: =IF(D17>=0,"Favorable","Unfavorable") -> Favorable
A18: Total spending | B18: =SUM(B7:B17) -> 240000 | C18: =SUM(C7:C17) -> 189016.02 | D18: =B18-C18 -> 50983.98 | E18: =IFERROR(D18/B18,0) -> 0.21243325 | F18: =IF(D18>=0,"Favorable","Unfavorable") -> Favorable
A20: By month
A21: Month | B21: Budget | C21: Actual | D21: Variance | E21: Variance % | F21: Utilization | G21: Status
A22: Jan 2025 | B22: ='Budget'!C17 -> 20000 | C22: ='Monthly P&L'!C42 -> 12760.2 | D22: =B22-C22 -> 7239.8 | E22: =IFERROR(D22/B22,0) -> 0.36199 | F22: =IFERROR(C22/B22,0) -> 0.63801 | G22: =IF(D22>=0,"Favorable","Unfavorable") -> Favorable
A23: Feb 2025 | B23: ='Budget'!D17 -> 20000 | C23: ='Monthly P&L'!D42 -> 16129.13 | D23: =B23-C23 -> 3870.87 | E23: =IFERROR(D23/B23,0) -> 0.1935435 | F23: =IFERROR(C23/B23,0) -> 0.8064565 | G23: =IF(D23>=0,"Favorable","Unfavorable") -> Favorable
A24: Mar 2025 | B24: ='Budget'!E17 -> 20000 | C24: ='Monthly P&L'!E42 -> 15058.62 | D24: =B24-C24 -> 4941.38 | E24: =IFERROR(D24/B24,0) -> 0.247069 | F24: =IFERROR(C24/B24,0) -> 0.752931 | G24: =IF(D24>=0,"Favorable","Unfavorable") -> Favorable
A25: Apr 2025 | B25: ='Budget'!F17 -> 20000 | C25: ='Monthly P&L'!F42 -> 14258.12 | D25: =B25-C25 -> 5741.88 | E25: =IFERROR(D25/B25,0) -> 0.287094 | F25: =IFERROR(C25/B25,0) -> 0.712906 | G25: =IF(D25>=0,"Favorable","Unfavorable") -> Favorable
A26: May 2025 | B26: ='Budget'!G17 -> 20000 | C26: ='Monthly P&L'!G42 -> 14844.23 | D26: =B26-C26 -> 5155.77 | E26: =IFERROR(D26/B26,0) -> 0.2577885 | F26: =IFERROR(C26/B26,0) -> 0.7422115 | G26: =IF(D26>=0,"Favorable","Unfavorable") -> Favorable
A27: Jun 2025 | B27: ='Budget'!H17 -> 20000 | C27: ='Monthly P&L'!H42 -> 15437.86 | D27: =B27-C27 -> 4562.14 | E27: =IFERROR(D27/B27,0) -> 0.228107 | F27: =IFERROR(C27/B27,0) -> 0.771893 | G27: =IF(D27>=0,"Favorable","Unfavorable") -> Favorable
A28: Jul 2025 | B28: ='Budget'!I17 -> 20000 | C28: ='Monthly P&L'!I42 -> 12670.69 | D28: =B28-C28 -> 7329.31 | E28: =IFERROR(D28/B28,0) -> 0.3664655 | F28: =IFERROR(C28/B28,0) -> 0.6335345 | G28: =IF(D28>=0,"Favorable","Unfavorable") -> Favorable
A29: Aug 2025 | B29: ='Budget'!J17 -> 20000 | C29: ='Monthly P&L'!J42 -> 13345.36 | D29: =B29-C29 -> 6654.64 | E29: =IFERROR(D29/B29,0) -> 0.332732 | F29: =IFERROR(C29/B29,0) -> 0.667268 | G29: =IF(D29>=0,"Favorable","Unfavorable") -> Favorable
A30: Sep 2025 | B30: ='Budget'!K17 -> 20000 | C30: ='Monthly P&L'!K42 -> 12926.06 | D30: =B30-C30 -> 7073.94 | E30: =IFERROR(D30/B30,0) -> 0.353697 | F30: =IFERROR(C30/B30,0) -> 0.646303 | G30: =IF(D30>=0,"Favorable","Unfavorable") -> Favorable
A31: Oct 2025 | B31: ='Budget'!L17 -> 20000 | C31: ='Monthly P&L'!L42 -> 14115.83 | D31: =B31-C31 -> 5884.17 | E31: =IFERROR(D31/B31,0) -> 0.2942085 | F31: =IFERROR(C31/B31,0) -> 0.7057915 | G31: =IF(D31>=0,"Favorable","Unfavorable") -> Favorable
A32: Nov 2025 | B32: ='Budget'!M17 -> 20000 | C32: ='Monthly P&L'!M42 -> 22442.88 | D32: =B32-C32 -> -2442.88 | E32: =IFERROR(D32/B32,0) -> -0.122144 | F32: =IFERROR(C32/B32,0) -> 1.122144 | G32: =IF(D32>=0,"Favorable","Unfavorable") -> Unfavorable
A33: Dec 2025 | B33: ='Budget'!N17 -> 20000 | C33: ='Monthly P&L'!N42 -> 25027.04 | D33: =B33-C33 -> -5027.04 | E33: =IFERROR(D33/B33,0) -> -0.251352 | F33: =IFERROR(C33/B33,0) -> 1.251352 | G33: =IF(D33>=0,"Favorable","Unfavorable") -> Unfavorable
A34: FY 2025 | B34: =SUM(B22:B33) -> 240000 | C34: =SUM(C22:C33) -> 189016.02 | D34: =B34-C34 -> 50983.98 | E34: =IFERROR(D34/B34,0) -> 0.21243325 | F34: =IFERROR(C34/B34,0) -> 0.78756675 | G34: =IF(D34>=0,"Favorable","Unfavorable") -> Favorable
A36: Highlights, found with INDEX and MATCH
A37: Largest overspend, month | B37: =INDEX(A22:A33,MATCH(MIN(D22:D33),D22:D33,0)) -> Dec 2025 | D37: =MIN(D22:D33) -> -5027.04
A38: Largest underspend, month | B38: =INDEX(A22:A33,MATCH(MAX(D22:D33),D22:D33,0)) -> Jul 2025 | D38: =MAX(D22:D33) -> 7329.31
A39: Line furthest over budget | B39: =INDEX(A7:A17,MATCH(MIN(D7:D17),D7:D17,0)) -> Marketplace fees | D39: =MIN(D7:D17) -> -1451.1
A40: Line furthest under budget | B40: =INDEX(A7:A17,MATCH(MAX(D7:D17),D7:D17,0)) -> Designer fragrance COGS | D40: =MAX(D7:D17) -> 42394

Sheet Forecast
A1: Forecast, FY2026
A2: Monthly forecast from 2025 results and the scenario chosen on the Assumptions sheet. USD.
A3: Illustrative figures for privacy: modeled on the business's size, channels and products, not its actual results
A4: USD | C4: 46053 | D4: 46081 | E4: 46112 | F4: 46142 | G4: 46173 | H4: 46203 | I4: 46234 | J4: 46265 | K4: 46295 | L4: 46326 | M4: 46356 | N4: 46387 | O4: FY 2026
A5: ="Scenario: "&CHOOSE('Assumptions'!$B$32,"Base","Upside","Downside")&" (choose it on the Assumptions sheet)" -> Scenario: Base (choose it on the Assumptions sheet)
A6: Net revenue: 2025 month grown by scenario | C6: ='Monthly P&L'!C11*(1+'Assumptions'!$E$34) -> 14978.909 | D6: ='Monthly P&L'!D11*(1+'Assumptions'!$E$34) -> 19124.963 | E6: ='Monthly P&L'!E11*(1+'Assumptions'!$E$34) -> 16707.856 | F6: ='Monthly P&L'!F11*(1+'Assumptions'!$E$34) -> 16004.527 | G6: ='Monthly P&L'!G11*(1+'Assumptions'!$E$34) -> 17752.999 | H6: ='Monthly P&L'!H11*(1+'Assumptions'!$E$34) -> 18657.518 | I6: ='Monthly P&L'!I11*(1+'Assumptions'!$E$34) -> 15053.071 | J6: ='Monthly P&L'!J11*(1+'Assumptions'!$E$34) -> 15660.403 | ... N6: ='Monthly P&L'!N11*(1+'Assumptions'!$E$34) -> 29502.704 | O6: =SUM(C6:N6) -> 223007.59
A7: Gross margin: 2025 margin plus scenario change | C7: ='Monthly P&L'!$O$19+'Assumptions'!$E$35 -> 0.31242681 | D7: ='Monthly P&L'!$O$19+'Assumptions'!$E$35 -> 0.31242681 | E7: ='Monthly P&L'!$O$19+'Assumptions'!$E$35 -> 0.31242681 | F7: ='Monthly P&L'!$O$19+'Assumptions'!$E$35 -> 0.31242681 | G7: ='Monthly P&L'!$O$19+'Assumptions'!$E$35 -> 0.31242681 | H7: ='Monthly P&L'!$O$19+'Assumptions'!$E$35 -> 0.31242681 | I7: ='Monthly P&L'!$O$19+'Assumptions'!$E$35 -> 0.31242681 | J7: ='Monthly P&L'!$O$19+'Assumptions'!$E$35 -> 0.31242681 | ... N7: ='Monthly P&L'!$O$19+'Assumptions'!$E$35 -> 0.31242681 | O7: =IFERROR(O9/O6,0) -> 0.31242681
A8: Cost of goods sold | C8: =C6*(1-C7) -> 10299.096 | D8: =D6*(1-D7) -> 13149.812 | E8: =E6*(1-E7) -> 11487.874 | F8: =F6*(1-F7) -> 11004.284 | G8: =G6*(1-G7) -> 12206.486 | H8: =H6*(1-H7) -> 12828.409 | I8: =I6*(1-I7) -> 10350.088 | J8: =J6*(1-J7) -> 10767.673 | ... N8: =N6*(1-N7) -> 20285.268 | O8: =SUM(C8:N8) -> 153334.04
A9: Gross profit | C9: =C6-C8 -> 4679.8128 | D9: =D6-D8 -> 5975.1513 | E9: =E6-E8 -> 5219.9822 | F9: =F6-F8 -> 5000.2434 | G9: =G6-G8 -> 5546.5129 | H9: =H6-H8 -> 5829.1089 | I9: =I6-I8 -> 4702.983 | J9: =J6-J8 -> 4892.7298 | ... N9: =N6-N8 -> 9217.4358 | O9: =SUM(C9:N9) -> 69673.55
A10: Variable costs at the 2025 rate | C10: =C6*'Assumptions'!$B$28 -> 3310.0322 | D10: =D6*'Assumptions'!$B$28 -> 4226.2252 | E10: =E6*'Assumptions'!$B$28 -> 3692.094 | F10: =F6*'Assumptions'!$B$28 -> 3536.6727 | G10: =G6*'Assumptions'!$B$28 -> 3923.0492 | H10: =H6*'Assumptions'!$B$28 -> 4122.9294 | I10: =I6*'Assumptions'!$B$28 -> 3326.4204 | J10: =J6*'Assumptions'!$B$28 -> 3460.6284 | ... N10: =N6*'Assumptions'!$B$28 -> 6519.4934 | O10: =SUM(C10:N10) -> 49280.11
A11: Fixed costs: software, fees, taxes, G&A | C11: ='Assumptions'!$B$29*(1+'Assumptions'!$E$36) -> 333.17113 | D11: ='Assumptions'!$B$29*(1+'Assumptions'!$E$36) -> 333.17113 | E11: ='Assumptions'!$B$29*(1+'Assumptions'!$E$36) -> 333.17113 | F11: ='Assumptions'!$B$29*(1+'Assumptions'!$E$36) -> 333.17113 | G11: ='Assumptions'!$B$29*(1+'Assumptions'!$E$36) -> 333.17113 | H11: ='Assumptions'!$B$29*(1+'Assumptions'!$E$36) -> 333.17113 | I11: ='Assumptions'!$B$29*(1+'Assumptions'!$E$36) -> 333.17113 | J11: ='Assumptions'!$B$29*(1+'Assumptions'!$E$36) -> 333.17113 | ... N11: ='Assumptions'!$B$29*(1+'Assumptions'!$E$36) -> 333.17113 | O11: =SUM(C11:N11) -> 3998.0535
A12: Depreciation at the December run rate | C12: ='Monthly P&L'!$N$31 -> 45.75 | D12: ='Monthly P&L'!$N$31 -> 45.75 | E12: ='Monthly P&L'!$N$31 -> 45.75 | F12: ='Monthly P&L'!$N$31 -> 45.75 | G12: ='Monthly P&L'!$N$31 -> 45.75 | H12: ='Monthly P&L'!$N$31 -> 45.75 | I12: ='Monthly P&L'!$N$31 -> 45.75 | J12: ='Monthly P&L'!$N$31 -> 45.75 | ... N12: ='Monthly P&L'!$N$31 -> 45.75 | O12: =SUM(C12:N12) -> 549
A13: Total operating expenses | C13: =SUM(C10:C12) -> 3688.9533 | D13: =SUM(D10:D12) -> 4605.1463 | E13: =SUM(E10:E12) -> 4071.0152 | F13: =SUM(F10:F12) -> 3915.5939 | G13: =SUM(G10:G12) -> 4301.9704 | H13: =SUM(H10:H12) -> 4501.8505 | I13: =SUM(I10:I12) -> 3705.3416 | J13: =SUM(J10:J12) -> 3839.5495 | ... N13: =SUM(N10:N12) -> 6898.4146 | O13: =SUM(C13:N13) -> 53827.164
A15: Net income | C15: =C9-C13 -> 990.85954 | D15: =D9-D13 -> 1370.005 | E15: =E9-E13 -> 1148.9671 | F15: =F9-F13 -> 1084.6495 | G15: =G9-G13 -> 1244.5426 | H15: =H9-H13 -> 1327.2584 | I15: =I9-I13 -> 997.64145 | J15: =J9-J13 -> 1053.1803 | ... N15: =N9-N13 -> 2319.0213 | O15: =SUM(C15:N15) -> 15846.386
A16: Net margin | C16: =IFERROR(C15/C6,0) -> 0.066150314 | D16: =IFERROR(D15/D6,0) -> 0.071634384 | E16: =IFERROR(E15/E6,0) -> 0.068768073 | F16: =IFERROR(F15/F6,0) -> 0.067771421 | G16: =IFERROR(G15/G6,0) -> 0.070103229 | H16: =IFERROR(H15/H6,0) -> 0.071137992 | I16: =IFERROR(I15/I6,0) -> 0.066274945 | J16: =IFERROR(J15/J6,0) -> 0.067251163 | ... O16: =IFERROR(O15/O6,0) -> 0.071057611
A18: Cash, simplified: before working capital changes
A19: Cash, beginning of month | C19: ='Monthly BS'!$N$6 -> 13286.169 | D19: =C24 -> 13422.779 | E19: =D24 -> 13938.534 | F19: =E24 -> 14233.251 | G19: =F24 -> 14463.65 | H19: =G24 -> 14853.943 | I19: =H24 -> 15326.951 | J19: =I24 -> 15470.343 | K19: =J24 -> 15669.273 | ... N19: =M24 -> 17416.784 | O19: =C19 -> 13286.169
A20: Net income | C20: =C15 -> 990.85954 | D20: =D15 -> 1370.005 | E20: =E15 -> 1148.9671 | F20: =F15 -> 1084.6495 | G20: =G15 -> 1244.5426 | H20: =H15 -> 1327.2584 | I20: =I15 -> 997.64145 | J20: =J15 -> 1053.1803 | ... N20: =N15 -> 2319.0213 | O20: =SUM(C20:N20) -> 15846.386
A21: Add back depreciation | C21: =C12 -> 45.75 | D21: =D12 -> 45.75 | E21: =E12 -> 45.75 | F21: =F12 -> 45.75 | G21: =G12 -> 45.75 | H21: =H12 -> 45.75 | I21: =I12 -> 45.75 | J21: =J12 -> 45.75 | ... N21: =N12 -> 45.75 | O21: =SUM(C21:N21) -> 549
A22: Member distributions | C22: =-'Assumptions'!$E$37 -> -800 | D22: =-'Assumptions'!$E$37 -> -800 | E22: =-'Assumptions'!$E$37 -> -800 | F22: =-'Assumptions'!$E$37 -> -800 | G22: =-'Assumptions'!$E$37 -> -800 | H22: =-'Assumptions'!$E$37 -> -800 | I22: =-'Assumptions'!$E$37 -> -800 | J22: =-'Assumptions'!$E$37 -> -800 | ... N22: =-'Assumptions'!$E$37 -> -800 | O22: =SUM(C22:N22) -> -9600
A23: Equipment purchases, spread evenly | C23: =-'Assumptions'!$E$38/12 -> -100 | D23: =-'Assumptions'!$E$38/12 -> -100 | E23: =-'Assumptions'!$E$38/12 -> -100 | F23: =-'Assumptions'!$E$38/12 -> -100 | G23: =-'Assumptions'!$E$38/12 -> -100 | H23: =-'Assumptions'!$E$38/12 -> -100 | I23: =-'Assumptions'!$E$38/12 -> -100 | J23: =-'Assumptions'!$E$38/12 -> -100 | ... N23: =-'Assumptions'!$E$38/12 -> -100 | O23: =SUM(C23:N23) -> -1200
A24: Cash, end of month | C24: =SUM(C19:C23) -> 13422.779 | D24: =SUM(D19:D23) -> 13938.534 | E24: =SUM(E19:E23) -> 14233.251 | F24: =SUM(F19:F23) -> 14463.65 | G24: =SUM(G19:G23) -> 14853.943 | H24: =SUM(H19:H23) -> 15326.951 | I24: =SUM(I19:I23) -> 15470.343 | J24: =SUM(J19:J23) -> 15669.273 | ... N24: =SUM(N19:N23) -> 18881.555 | O24: =N24 -> 18881.555
A26: Spending budget, phased to the forecast
A27: Forecast spending: COGS plus cash opex | C27: =C8+C10+C11 -> 13942.299 | D27: =D8+D10+D11 -> 17709.208 | E27: =E8+E10+E11 -> 15513.139 | F27: =F8+F10+F11 -> 14874.127 | G27: =G8+G10+G11 -> 16462.706 | H27: =H8+H10+H11 -> 17284.51 | I27: =I8+I10+I11 -> 14009.68 | J27: =J8+J10+J11 -> 14561.473 | ... N27: =N8+N10+N11 -> 27137.933 | O27: =SUM(C27:N27) -> 206612.2
A28: Flat budget at the 2025 level | C28: ='Assumptions'!$B$25 -> 20000 | D28: ='Assumptions'!$B$25 -> 20000 | E28: ='Assumptions'!$B$25 -> 20000 | F28: ='Assumptions'!$B$25 -> 20000 | G28: ='Assumptions'!$B$25 -> 20000 | H28: ='Assumptions'!$B$25 -> 20000 | I28: ='Assumptions'!$B$25 -> 20000 | J28: ='Assumptions'!$B$25 -> 20000 | ... N28: ='Assumptions'!$B$25 -> 20000 | O28: =SUM(C28:N28) -> 240000
A29: Flat budget less forecast spending | C29: =C28-C27 -> 6057.7005 | D29: =D28-D27 -> 2290.792 | E29: =E28-E27 -> 4486.8611 | F29: =F28-F27 -> 5125.8725 | G29: =G28-G27 -> 3537.2936 | H29: =H28-H27 -> 2715.4904 | I29: =I28-I27 -> 5990.3205 | J29: =J28-J27 -> 5438.5273 | ... N29: =N28-N27 -> -7137.9327 | O29: =SUM(C29:N29) -> 33387.799
A30: Phasing: month's share of annual spending | C30: =IFERROR(C27/$O$27,0) -> 0.067480524 | D30: =IFERROR(D27/$O$27,0) -> 0.085712305 | E30: =IFERROR(E27/$O$27,0) -> 0.075083363 | F30: =IFERROR(F27/$O$27,0) -> 0.071990557 | G30: =IFERROR(G27/$O$27,0) -> 0.079679256 | H30: =IFERROR(H27/$O$27,0) -> 0.083656771 | I30: =IFERROR(I27/$O$27,0) -> 0.067806642 | J30: =IFERROR(J27/$O$27,0) -> 0.070477313 | ... N30: =IFERROR(N27/$O$27,0) -> 0.13134719 | O30: =SUM(C30:N30) -> 1

Sheet KPIs
A1: KPIs
A2: Monthly key performance indicators; the charts are on the next page
A3: Illustrative figures for privacy: modeled on the business's size, channels and products, not its actual results
A4: USD | C4: 45688 | D4: 45716 | E4: 45747 | F4: 45777 | G4: 45808 | H4: 45838 | I4: 45869 | J4: 45900 | K4: 45930 | L4: 45961 | M4: 45991 | N4: 46022 | O4: FY 2025
A5: Volume
A6: Orders | C6: ='Data'!C39 -> 182 | D6: ='Data'!D39 -> 232 | E6: ='Data'!E39 -> 188 | F6: ='Data'!F39 -> 191 | G6: ='Data'!G39 -> 224 | H6: ='Data'!H39 -> 222 | I6: ='Data'!I39 -> 193 | J6: ='Data'!J39 -> 189 | ... O6: ='Data'!O39 -> 2752
A7: Units sold | C7: ='Data'!C42 -> 288 | D7: ='Data'!D42 -> 359 | E7: ='Data'!E42 -> 299 | F7: ='Data'!F42 -> 300 | G7: ='Data'!G42 -> 347 | H7: ='Data'!H42 -> 350 | I7: ='Data'!I42 -> 311 | J7: ='Data'!J42 -> 297 | ... O7: ='Data'!O42 -> 4399
A8: Average order value, merchandise | C8: =IFERROR(('Data'!C6+'Data'!C7)/'Data'!C39,0) -> 72.756758 | D8: =IFERROR(('Data'!D6+'Data'!D7)/'Data'!D39,0) -> 75.755 | E8: =IFERROR(('Data'!E6+'Data'!E7)/'Data'!E39,0) -> 80.077287 | F8: =IFERROR(('Data'!F6+'Data'!F7)/'Data'!F39,0) -> 75.772618 | G8: =IFERROR(('Data'!G6+'Data'!G7)/'Data'!G39,0) -> 70.742768 | H8: =IFERROR(('Data'!H6+'Data'!H7)/'Data'!H39,0) -> 74.317252 | I8: =IFERROR(('Data'!I6+'Data'!I7)/'Data'!I39,0) -> 71.349482 | J8: =IFERROR(('Data'!J6+'Data'!J7)/'Data'!J39,0) -> 74.905185 | ... O8: =IFERROR(('Data'!O6+'Data'!O7)/'Data'!O39,0) -> 73.021664
A10: Profitability
A11: Gross margin | C11: ='Monthly P&L'!C19 -> 0.30047609 | D11: ='Monthly P&L'!D19 -> 0.30027786 | E11: ='Monthly P&L'!E19 -> 0.28990201 | F11: ='Monthly P&L'!F19 -> 0.3059142 | G11: ='Monthly P&L'!G19 -> 0.3085081 | H11: ='Monthly P&L'!H19 -> 0.30333794 | I11: ='Monthly P&L'!I19 -> 0.31488 | J11: ='Monthly P&L'!J19 -> 0.29738781 | ... O11: ='Monthly P&L'!O19 -> 0.30742681
A12: Operating margin | C12: ='Monthly P&L'!C35 -> 0.062934423 | D12: ='Monthly P&L'!D35 -> 0.069678305 | E12: ='Monthly P&L'!E35 -> 0.0055691766 | F12: ='Monthly P&L'!F35 -> 0.016887097 | G12: ='Monthly P&L'!G35 -> 0.077396557 | H12: ='Monthly P&L'!H35 -> 0.087125576 | I12: ='Monthly P&L'!I35 -> 0.070748819 | J12: ='Monthly P&L'!J35 -> 0.059397067 | ... O12: ='Monthly P&L'!O35 -> 0.065183388
A13: Own brand share of merchandise sales | C13: =IFERROR(('Data'!C9+'Data'!C10)/('Data'!C6+'Data'!C7),0) -> 0.14687582 | D13: =IFERROR(('Data'!D9+'Data'!D10)/('Data'!D6+'Data'!D7),0) -> 0.13481926 | E13: =IFERROR(('Data'!E9+'Data'!E10)/('Data'!E6+'Data'!E7),0) -> 0.13210974 | F13: =IFERROR(('Data'!F9+'Data'!F10)/('Data'!F6+'Data'!F7),0) -> 0.1460563 | G13: =IFERROR(('Data'!G9+'Data'!G10)/('Data'!G6+'Data'!G7),0) -> 0.15154691 | H13: =IFERROR(('Data'!H9+'Data'!H10)/('Data'!H6+'Data'!H7),0) -> 0.14700975 | I13: =IFERROR(('Data'!I9+'Data'!I10)/('Data'!I6+'Data'!I7),0) -> 0.15342491 | J13: =IFERROR(('Data'!J9+'Data'!J10)/('Data'!J6+'Data'!J7),0) -> 0.13547215 | ... O13: =IFERROR(('Data'!O9+'Data'!O10)/('Data'!O6+'Data'!O7),0) -> 0.14928177
A14: Own brand share of product gross profit | C14: =IFERROR((('Data'!C9+'Data'!C10)-'Data'!C17)/(('Data'!C6+'Data'!C7)-'Data'!C16-'Data'!C17),0) -> 0.40911366 | D14: =IFERROR((('Data'!D9+'Data'!D10)-'Data'!D17)/(('Data'!D6+'Data'!D7)-'Data'!D16-'Data'!D17),0) -> 0.34399655 | E14: =IFERROR((('Data'!E9+'Data'!E10)-'Data'!E17)/(('Data'!E6+'Data'!E7)-'Data'!E16-'Data'!E17),0) -> 0.36548228 | F14: =IFERROR((('Data'!F9+'Data'!F10)-'Data'!F17)/(('Data'!F6+'Data'!F7)-'Data'!F16-'Data'!F17),0) -> 0.38024472 | G14: =IFERROR((('Data'!G9+'Data'!G10)-'Data'!G17)/(('Data'!G6+'Data'!G7)-'Data'!G16-'Data'!G17),0) -> 0.40253674 | H14: =IFERROR((('Data'!H9+'Data'!H10)-'Data'!H17)/(('Data'!H6+'Data'!H7)-'Data'!H16-'Data'!H17),0) -> 0.4094505 | I14: =IFERROR((('Data'!I9+'Data'!I10)-'Data'!I17)/(('Data'!I6+'Data'!I7)-'Data'!I16-'Data'!I17),0) -> 0.37910964 | J14: =IFERROR((('Data'!J9+'Data'!J10)-'Data'!J17)/(('Data'!J6+'Data'!J7)-'Data'!J16-'Data'!J17),0) -> 0.36228329 | ... O14: =IFERROR((('Data'!O9+'Data'!O10)-'Data'!O17)/(('Data'!O6+'Data'!O7)-'Data'!O16-'Data'!O17),0) -> 0.38972395
A16: Efficiency
A17: Return rate, share of merchandise sales | C17: =IFERROR('Data'!C13/('Data'!C6+'Data'!C7),0) -> 0.0081031708 | D17: =IFERROR('Data'!D13/('Data'!D6+'Data'!D7),0) -> 0.044146967 | E17: =IFERROR('Data'!E13/('Data'!E6+'Data'!E7),0) -> 0.022701473 | F17: =IFERROR('Data'!F13/('Data'!F6+'Data'!F7),0) -> 0.030870813 | G17: =IFERROR('Data'!G13/('Data'!G6+'Data'!G7),0) -> 0.016675102 | H17: =IFERROR('Data'!H13/('Data'!H6+'Data'!H7),0) -> 0.0079025701 | I17: =IFERROR('Data'!I13/('Data'!I6+'Data'!I7),0) -> 0.042138783 | J17: =IFERROR('Data'!J13/('Data'!J6+'Data'!J7),0) -> 0.026761168 | ... O17: =IFERROR('Data'!O13/('Data'!O6+'Data'!O7),0) -> 0.026146221
A18: eBay fee rate, share of eBay sales | C18: =IFERROR('Data'!C20/'Data'!C6,0) -> 0.13605702 | D18: =IFERROR('Data'!D20/'Data'!D6,0) -> 0.13614469 | E18: =IFERROR('Data'!E20/'Data'!E6,0) -> 0.13564653 | F18: =IFERROR('Data'!F20/'Data'!F6,0) -> 0.13566108 | G18: =IFERROR('Data'!G20/'Data'!G6,0) -> 0.13636314 | H18: =IFERROR('Data'!H20/'Data'!H6,0) -> 0.13575936 | I18: =IFERROR('Data'!I20/'Data'!I6,0) -> 0.13600701 | J18: =IFERROR('Data'!J20/'Data'!J6,0) -> 0.13624899 | ... O18: =IFERROR('Data'!O20/'Data'!O6,0) -> 0.13608468
A19: Advertising, share of net revenue | C19: =IFERROR('Monthly P&L'!C25/'Monthly P&L'!C11,0) -> 0.033378399 | D19: =IFERROR('Monthly P&L'!D25/'Monthly P&L'!D11,0) -> 0.029264946 | E19: =IFERROR('Monthly P&L'!E25/'Monthly P&L'!E11,0) -> 0.033805475 | F19: =IFERROR('Monthly P&L'!F25/'Monthly P&L'!F11,0) -> 0.031992698 | G19: =IFERROR('Monthly P&L'!G25/'Monthly P&L'!G11,0) -> 0.026852815 | H19: =IFERROR('Monthly P&L'!H25/'Monthly P&L'!H11,0) -> 0.024294014 | I19: =IFERROR('Monthly P&L'!I25/'Monthly P&L'!I11,0) -> 0.030309231 | J19: =IFERROR('Monthly P&L'!J25/'Monthly P&L'!J11,0) -> 0.03346274 | ... O19: =IFERROR('Monthly P&L'!O25/'Monthly P&L'!O11,0) -> 0.033314858
A20: Inventory, days on hand | C20: =IFERROR('Monthly BS'!C8/'Data'!C17*DAY(C$4),0) -> 20.112943 | D20: =IFERROR('Monthly BS'!D8/'Data'!D17*DAY(D$4),0) -> 119.29178 | E20: =IFERROR('Monthly BS'!E8/'Data'!E17*DAY(E$4),0) -> 125.70675 | F20: =IFERROR('Monthly BS'!F8/'Data'!F17*DAY(F$4),0) -> 85.712859 | G20: =IFERROR('Monthly BS'!G8/'Data'!G17*DAY(G$4),0) -> 46.495486 | H20: =IFERROR('Monthly BS'!H8/'Data'!H17*DAY(H$4),0) -> 151.32192 | I20: =IFERROR('Monthly BS'!I8/'Data'!I17*DAY(I$4),0) -> 146.98623 | J20: =IFERROR('Monthly BS'!J8/'Data'!J17*DAY(J$4),0) -> 127.98293 | ... N20: =IFERROR('Monthly BS'!N8/'Data'!N17*DAY(N$4),0) -> 72.889965 | O20: =IFERROR('Monthly BS'!N8/'Data'!O17*365,0) -> 125.29638
A22: Cash and budget
A23: Cash balance, month end | C23: ='Monthly BS'!C6 -> 4682.3971 | D23: ='Monthly BS'!D6 -> 7248.3204 | E23: ='Monthly BS'!E6 -> 6364.4223 | F23: ='Monthly BS'!F6 -> 5931.663 | G23: ='Monthly BS'!G6 -> 7390.649 | H23: ='Monthly BS'!H6 -> 6928.552 | I23: ='Monthly BS'!I6 -> 6234.8968 | J23: ='Monthly BS'!J6 -> 7184.9545 | ... N23: ='Monthly BS'!N6 -> 13286.169 | O23: ='Monthly BS'!N6 -> 13286.169
A24: Budget utilization: spending over budget | C24: =IFERROR('Monthly P&L'!C42/'Budget'!C17,0) -> 0.63801 | D24: =IFERROR('Monthly P&L'!D42/'Budget'!D17,0) -> 0.8064565 | E24: =IFERROR('Monthly P&L'!E42/'Budget'!E17,0) -> 0.752931 | F24: =IFERROR('Monthly P&L'!F42/'Budget'!F17,0) -> 0.712906 | G24: =IFERROR('Monthly P&L'!G42/'Budget'!G17,0) -> 0.7422115 | H24: =IFERROR('Monthly P&L'!H42/'Budget'!H17,0) -> 0.771893 | I24: =IFERROR('Monthly P&L'!I42/'Budget'!I17,0) -> 0.6335345 | J24: =IFERROR('Monthly P&L'!J42/'Budget'!J17,0) -> 0.667268 | ... O24: =IFERROR('Monthly P&L'!O42/'Budget'!O17,0) -> 0.78756675
Q26: Chart data
A27: Charts | Q27: Month | R27: Jan | S27: Feb | T27: Mar | U27: Apr | V27: May | W27: Jun | X27: Jul | Y27: Aug | Z27: Sep | AA27: Oct | AB27: Nov | AC27: Dec
Q28: Net revenue | R28: ='Monthly P&L'!C11 -> 13617.19 | S28: ='Monthly P&L'!D11 -> 17386.33 | T28: ='Monthly P&L'!E11 -> 15188.96 | U28: ='Monthly P&L'!F11 -> 14549.57 | V28: ='Monthly P&L'!G11 -> 16139.09 | W28: ='Monthly P&L'!H11 -> 16961.38 | X28: ='Monthly P&L'!I11 -> 13684.61 | Y28: ='Monthly P&L'!J11 -> 14236.73 | ... AC28: ='Monthly P&L'!N11 -> 26820.64
Q29: Net income | R29: ='Monthly P&L'!C37 -> 856.99 | S29: ='Monthly P&L'!D37 -> 1211.45 | T29: ='Monthly P&L'!E37 -> 84.59 | U29: ='Monthly P&L'!F37 -> 245.7 | V29: ='Monthly P&L'!G37 -> 1249.11 | W29: ='Monthly P&L'!H37 -> 1477.77 | X29: ='Monthly P&L'!I37 -> 968.17 | Y29: ='Monthly P&L'!J37 -> 845.62 | ... AC29: ='Monthly P&L'!N37 -> 1747.85
Q30: Spending | R30: ='Monthly P&L'!C42 -> 12760.2 | S30: ='Monthly P&L'!D42 -> 16129.13 | T30: ='Monthly P&L'!E42 -> 15058.62 | U30: ='Monthly P&L'!F42 -> 14258.12 | V30: ='Monthly P&L'!G42 -> 14844.23 | W30: ='Monthly P&L'!H42 -> 15437.86 | X30: ='Monthly P&L'!I42 -> 12670.69 | Y30: ='Monthly P&L'!J42 -> 13345.36 | ... AC30: ='Monthly P&L'!N42 -> 25027.04
Q31: Budget | R31: ='Budget'!C17 -> 20000 | S31: ='Budget'!D17 -> 20000 | T31: ='Budget'!E17 -> 20000 | U31: ='Budget'!F17 -> 20000 | V31: ='Budget'!G17 -> 20000 | W31: ='Budget'!H17 -> 20000 | X31: ='Budget'!I17 -> 20000 | Y31: ='Budget'!J17 -> 20000 | ... AC31: ='Budget'!N17 -> 20000
Q32: Gross margin | R32: ='Monthly P&L'!C19 -> 0.30047609 | S32: ='Monthly P&L'!D19 -> 0.30027786 | T32: ='Monthly P&L'!E19 -> 0.28990201 | U32: ='Monthly P&L'!F19 -> 0.3059142 | V32: ='Monthly P&L'!G19 -> 0.3085081 | W32: ='Monthly P&L'!H19 -> 0.30333794 | X32: ='Monthly P&L'!I19 -> 0.31488 | Y32: ='Monthly P&L'!J19 -> 0.29738781 | ... AC32: ='Monthly P&L'!N19 -> 0.31986336
Q33: Operating margin | R33: ='Monthly P&L'!C35 -> 0.062934423 | S33: ='Monthly P&L'!D35 -> 0.069678305 | T33: ='Monthly P&L'!E35 -> 0.0055691766 | U33: ='Monthly P&L'!F35 -> 0.016887097 | V33: ='Monthly P&L'!G35 -> 0.077396557 | W33: ='Monthly P&L'!H35 -> 0.087125576 | X33: ='Monthly P&L'!I35 -> 0.070748819 | Y33: ='Monthly P&L'!J35 -> 0.059397067 | ... AC33: ='Monthly P&L'!N35 -> 0.065168094
Q35: eBay | R35: ='Data'!O6 -> 116479.68
Q36: Shopify | R36: ='Data'!O7 -> 84475.94

Sheet SQL Analysis
A1: SQL Analysis
A2: Each table is the result of a query in 5_SQLite_Database/queries/, run against escentials.db; each chart reads its table
A3: Illustrative figures for privacy: modeled on the business's size, channels and products, not its actual results
A5: Revenue by channel · 5_SQLite_Database/queries/revenue_by_channel.sql
A6: Merchandise sales by channel, with order count, average order value and share of the total.
A7: Channel | B7: Orders | C7: Merchandise sales | D7: Avg order value | E7: Share of sales
A8: eBay | B8: 1044 | C8: 116479.68 | D8: 111.57 | E8: 0.5796
A9: Shopify | B9: 1708 | C9: 84475.94 | D9: 49.46 | E9: 0.4204
A26: Gross margin by product line · 5_SQLite_Database/queries/margin_by_product_line.sql
A27: Gross margin by product line, before returns: the own brand line is small in sales but rich in margin.
A28: Product line | B28: Units | C28: Merchandise sales | D28: Cost of goods | E28: Gross profit | F28: Gross margin | G28: Share of gross profit
A29: Designer fragrance | B29: 1200 | C29: 170956.61 | D29: 138119 | E29: 32837.61 | F29: 0.1921 | G29: 0.5823
A30: Refills | B30: 2321 | C30: 22255.79 | D30: 4307.1 | E30: 17948.69 | F30: 0.8065 | G30: 0.3183
A31: Car Perfume | B31: 878 | C31: 7743.22 | D31: 2136.1 | E31: 5607.12 | F31: 0.7241 | G31: 0.0994
A48: Top ten products by gross profit · 5_SQLite_Database/queries/top_products.sql
A49: The ten products that earned the most gross profit, ranked, with units, sales and margin.
A50: Product | B50: Rank | C50: Product line | D50: Units | E50: Merchandise sales | F50: Gross profit | G50: Gross margin
A51: Car Perfume refill, 3 x 10 ml | B51: 1 | C51: Refills | D51: 552 | E51: 8274.48 | F51: 6535.68 | G51: 0.7899
A52: Parfums de Marly Layton EDP 4.2 oz | B52: 2 | C52: Designer fragrance | D52: 187 | E52: 34158.11 | F52: 6482.11 | G52: 0.1898
A53: Car Perfume refill, 2 x 10 ml | B53: 3 | C53: Refills | D53: 677 | E53: 7440.23 | F53: 6018.53 | G53: 0.8089
A54: Car Perfume refill, 10 ml | B54: 4 | C54: Refills | D54: 1092 | E54: 6541.08 | F54: 5394.48 | G54: 0.8247
A55: Creed Aventus EDP 3.3 oz | B55: 5 | C55: Designer fragrance | D55: 86 | E55: 25049.19 | F55: 4065.19 | G55: 0.1623
A56: Dior Sauvage EDT 3.4 oz | B56: 6 | C56: Designer fragrance | D56: 155 | E56: 14980.95 | F56: 3200.95 | G56: 0.2137
A57: Car Perfume bottle, Onyx, Chrome or Gold | B57: 7 | C57: Car Perfume | D57: 514 | E57: 4106.86 | F57: 2898.96 | G57: 0.7059
A58: Car Perfume bottle, color collection | B58: 8 | C58: Car Perfume | D58: 364 | E58: 3636.36 | F58: 2708.16 | G58: 0.7447
A59: Versace Eros EDT 3.4 oz | B59: 9 | C59: Designer fragrance | D59: 175 | E59: 10680.16 | F59: 2630.16 | G59: 0.2463
A60: Maison Francis Kurkdjian Baccarat Rouge 540 EDP 2.4 oz | B60: 10 | C60: Designer fragrance | D60: 55 | E60: 14407.46 | F60: 2362.46 | G60: 0.164
A77: Operating costs by category · 5_SQLite_Database/queries/expense_mix.sql
A78: Where the money goes after the product itself: every operating cost, from order level fees and the ledger.
A79: Category | B79: Amount | C79: Share
A80: Shipping and fulfillment | B80: 17934.9 | C80: 0.369
A81: Marketplace fees | B81: 15851.1 | C81: 0.3261
A82: Advertising and marketing | B82: 6754.06 | C82: 0.139
A83: Payment processing | B83: 3223.94 | C83: 0.0663
A84: Packaging and supplies | B84: 1036.1 | C84: 0.0213
A85: General and administrative | B85: 1003.27 | C85: 0.0206
A86: Professional fees | B86: 970 | C86: 0.02
A87: Software and subscriptions | B87: 924.4 | C87: 0.019
A88: Taxes and licenses | B88: 910 | C88: 0.0187

Sheet Monthly P&L
A1: Monthly P&L
A2: Income statement by month. USD.
A3: Illustrative figures for privacy: modeled on the business's size, channels and products, not its actual results
A4: USD | C4: 45688 | D4: 45716 | E4: 45747 | F4: 45777 | G4: 45808 | H4: 45838 | I4: 45869 | J4: 45900 | K4: 45930 | L4: 45961 | M4: 45991 | N4: 46022 | O4: FY 2025
A5: Revenue
A6: Merchandise sales, eBay | C6: ='Data'!C6 -> 7868.76 | D6: ='Data'!D6 -> 10203.63 | E6: ='Data'!E6 -> 7998.73 | F6: ='Data'!F6 -> 9112.12 | G6: ='Data'!G6 -> 9220.82 | H6: ='Data'!H6 -> 9203.27 | I6: ='Data'!I6 -> 9009.83 | J6: ='Data'!J6 -> 8318.08 | ... N6: ='Data'!N6 -> 17077.67 | O6: =SUM(C6:N6) -> 116479.68
A7: Merchandise sales, Shopify | C7: ='Data'!C7 -> 5372.97 | D7: ='Data'!D7 -> 7371.53 | E7: ='Data'!E7 -> 7055.8 | F7: ='Data'!F7 -> 5360.45 | G7: ='Data'!G7 -> 6625.56 | H7: ='Data'!H7 -> 7295.16 | I7: ='Data'!I7 -> 4760.62 | J7: ='Data'!J7 -> 5839 | ... N7: ='Data'!N7 -> 10181.47 | O7: =SUM(C7:N7) -> 84475.94
A8: Shipping income | C8: ='Data'!C11 -> 509.15 | D8: ='Data'!D11 -> 616.97 | E8: ='Data'!E11 -> 539.1 | F8: ='Data'!F11 -> 581.03 | G8: ='Data'!G11 -> 599 | H8: ='Data'!H11 -> 640.93 | I8: ='Data'!I11 -> 527.12 | J8: ='Data'!J11 -> 479.2 | ... N8: ='Data'!N11 -> 1042.26 | O8: =SUM(C8:N8) -> 7631.26
A9: Less: discounts | C9: =-'Data'!C12 -> -26.39 | D9: =-'Data'!D12 -> -29.91 | E9: =-'Data'!E12 -> -62.91 | F9: =-'Data'!F12 -> -57.25 | G9: =-'Data'!G12 -> -42.05 | H9: =-'Data'!H12 -> -47.6 | I9: =-'Data'!I12 -> -32.69 | J9: =-'Data'!J12 -> -20.69 | ... N9: =-'Data'!N12 -> -84.34 | O9: =SUM(C9:N9) -> -598.48
A10: Less: returns and refunds | C10: =-'Data'!C13 -> -107.3 | D10: =-'Data'!D13 -> -775.89 | E10: =-'Data'!E13 -> -341.76 | F10: =-'Data'!F13 -> -446.78 | G10: =-'Data'!G13 -> -264.24 | H10: =-'Data'!H13 -> -130.38 | I10: =-'Data'!I13 -> -580.27 | J10: =-'Data'!J13 -> -378.86 | ... N10: =-'Data'!N13 -> -1396.42 | O10: =SUM(C10:N10) -> -5254.23
A11: Net revenue | C11: =SUM(C6:C10) -> 13617.19 | D11: =SUM(D6:D10) -> 17386.33 | E11: =SUM(E6:E10) -> 15188.96 | F11: =SUM(F6:F10) -> 14549.57 | G11: =SUM(G6:G10) -> 16139.09 | H11: =SUM(H6:H10) -> 16961.38 | I11: =SUM(I6:I10) -> 13684.61 | J11: =SUM(J6:J10) -> 14236.73 | ... N11: =SUM(N6:N10) -> 26820.64 | O11: =SUM(C11:N11) -> 202734.17
A13: Cost of goods sold
A14: Designer fragrance, drop shipped | C14: ='Data'!C16 -> 9101 | D14: ='Data'!D16 -> 11657 | E14: ='Data'!E16 -> 10357 | F14: ='Data'!F16 -> 9648 | G14: ='Data'!G16 -> 10645 | H14: ='Data'!H16 -> 11308 | I14: ='Data'!I16 -> 8929 | J14: ='Data'!J16 -> 9590 | ... N14: ='Data'!N16 -> 17307 | O14: =SUM(C14:N14) -> 134006
A15: Car Perfume and refills | C15: ='Data'!C17 -> 424.55 | D15: ='Data'!D17 -> 508.6 | E15: ='Data'!E17 -> 428.65 | F15: ='Data'!F17 -> 450.65 | G15: ='Data'!G17 -> 515.05 | H15: ='Data'!H17 -> 508.35 | I15: ='Data'!I17 -> 446.6 | J15: ='Data'!J17 -> 412.9 | ... N15: ='Data'!N17 -> 934.7 | O15: =SUM(C15:N15) -> 6402.25
A16: Total cost of goods sold | C16: =C14+C15 -> 9525.55 | D16: =D14+D15 -> 12165.6 | E16: =E14+E15 -> 10785.65 | F16: =F14+F15 -> 10098.65 | G16: =G14+G15 -> 11160.05 | H16: =H14+H15 -> 11816.35 | I16: =I14+I15 -> 9375.6 | J16: =J14+J15 -> 10002.9 | ... N16: =N14+N15 -> 18241.7 | O16: =SUM(C16:N16) -> 140408.25
A18: Gross profit | C18: =C11-C16 -> 4091.64 | D18: =D11-D16 -> 5220.73 | E18: =E11-E16 -> 4403.31 | F18: =F11-F16 -> 4450.92 | G18: =G11-G16 -> 4979.04 | H18: =H11-H16 -> 5145.03 | I18: =I11-I16 -> 4309.01 | J18: =J11-J16 -> 4233.83 | ... N18: =N11-N16 -> 8578.94 | O18: =SUM(C18:N18) -> 62325.92
A19: Gross margin | C19: =IFERROR(C18/C11,0) -> 0.30047609 | D19: =IFERROR(D18/D11,0) -> 0.30027786 | E19: =IFERROR(E18/E11,0) -> 0.28990201 | F19: =IFERROR(F18/F11,0) -> 0.3059142 | G19: =IFERROR(G18/G11,0) -> 0.3085081 | H19: =IFERROR(H18/H11,0) -> 0.30333794 | I19: =IFERROR(I18/I11,0) -> 0.31488 | J19: =IFERROR(J18/J11,0) -> 0.29738781 | ... O19: =IFERROR(O18/O11,0) -> 0.30742681
A21: Operating expenses
A22: Marketplace fees | C22: ='Data'!C20 -> 1070.6 | D22: ='Data'!D20 -> 1389.17 | E22: ='Data'!E20 -> 1085 | F22: ='Data'!F20 -> 1236.16 | G22: ='Data'!G20 -> 1257.38 | H22: ='Data'!H20 -> 1249.43 | I22: ='Data'!I20 -> 1225.4 | J22: ='Data'!J20 -> 1133.33 | ... N22: ='Data'!N20 -> 2328.01 | O22: =SUM(C22:N22) -> 15851.1
A23: Payment processing | C23: ='Data'!C21 -> 205.33 | D23: ='Data'!D21 -> 276.92 | E23: ='Data'!E21 -> 260.3 | F23: ='Data'!F21 -> 209.63 | G23: ='Data'!G21 -> 253.99 | H23: ='Data'!H21 -> 278.32 | I23: ='Data'!I21 -> 187.72 | J23: ='Data'!J21 -> 219.69 | ... N23: ='Data'!N21 -> 399.29 | O23: =SUM(C23:N23) -> 3223.94
A24: Shipping and fulfillment | C24: ='Data'!C22 -> 1183.1 | D24: ='Data'!D22 -> 1524.2 | E24: ='Data'!E22 -> 1229.8 | F24: ='Data'!F22 -> 1232.55 | G24: ='Data'!G22 -> 1453.35 | H24: ='Data'!H22 -> 1434.35 | I24: ='Data'!I22 -> 1251.55 | J24: ='Data'!J22 -> 1249.6 | ... N24: ='Data'!N22 -> 2556.55 | O24: =SUM(C24:N24) -> 17934.9
A25: Advertising and marketing | C25: ='Data'!C23 -> 454.52 | D25: ='Data'!D23 -> 508.81 | E25: ='Data'!E23 -> 513.47 | F25: ='Data'!F23 -> 465.48 | G25: ='Data'!G23 -> 433.38 | H25: ='Data'!H23 -> 412.06 | I25: ='Data'!I23 -> 414.77 | J25: ='Data'!J23 -> 476.4 | ... N25: ='Data'!N23 -> 1214.34 | O25: =SUM(C25:N25) -> 6754.06
A26: Packaging and supplies | C26: ='Data'!C24 -> 68.9 | D26: ='Data'!D24 -> 85.8 | E26: ='Data'!E24 -> 70.2 | F26: ='Data'!F24 -> 73.45 | G26: ='Data'!G24 -> 85.15 | H26: ='Data'!H24 -> 85.15 | I26: ='Data'!I24 -> 73.45 | J26: ='Data'!J24 -> 68.9 | ... N26: ='Data'!N24 -> 144.95 | O26: =SUM(C26:N26) -> 1036.1
A27: Software and subscriptions | C27: ='Data'!C25 -> 75.2 | D27: ='Data'!D25 -> 75.2 | E27: ='Data'!E25 -> 97.2 | F27: ='Data'!F25 -> 75.2 | G27: ='Data'!G25 -> 75.2 | H27: ='Data'!H25 -> 75.2 | I27: ='Data'!I25 -> 75.2 | J27: ='Data'!J25 -> 75.2 | ... N27: ='Data'!N25 -> 75.2 | O27: =SUM(C27:N27) -> 924.4
A28: Professional fees | C28: ='Data'!C26 -> 0 | D28: ='Data'!D26 -> 0 | E28: ='Data'!E26 -> 950 | F28: ='Data'!F26 -> 0 | G28: ='Data'!G26 -> 0 | H28: ='Data'!H26 -> 20 | I28: ='Data'!I26 -> 0 | J28: ='Data'!J26 -> 0 | ... N28: ='Data'!N26 -> 0 | O28: =SUM(C28:N28) -> 970
A29: Taxes and licenses | C29: ='Data'!C27 -> 110 | D29: ='Data'!D27 -> 0 | E29: ='Data'!E27 -> 0 | F29: ='Data'!F27 -> 800 | G29: ='Data'!G27 -> 0 | H29: ='Data'!H27 -> 0 | I29: ='Data'!I27 -> 0 | J29: ='Data'!J27 -> 0 | ... N29: ='Data'!N27 -> 0 | O29: =SUM(C29:N29) -> 910
A30: General and administrative | C30: ='Data'!C28 -> 67 | D30: ='Data'!D28 -> 103.43 | E30: ='Data'!E28 -> 67 | F30: ='Data'!F28 -> 67 | G30: ='Data'!G28 -> 125.73 | H30: ='Data'!H28 -> 67 | I30: ='Data'!I28 -> 67 | J30: ='Data'!J28 -> 119.34 | ... N30: ='Data'!N28 -> 67 | O30: =SUM(C30:N30) -> 1003.27
A31: Depreciation | C31: ='Schedules'!C10 -> 0 | D31: ='Schedules'!D10 -> 45.75 | E31: ='Schedules'!E10 -> 45.75 | F31: ='Schedules'!F10 -> 45.75 | G31: ='Schedules'!G10 -> 45.75 | H31: ='Schedules'!H10 -> 45.75 | I31: ='Schedules'!I10 -> 45.75 | J31: ='Schedules'!J10 -> 45.75 | ... N31: ='Schedules'!N10 -> 45.75 | O31: =SUM(C31:N31) -> 503.25
A32: Total operating expenses | C32: =SUM(C22:C31) -> 3234.65 | D32: =SUM(D22:D31) -> 4009.28 | E32: =SUM(E22:E31) -> 4318.72 | F32: =SUM(F22:F31) -> 4205.22 | G32: =SUM(G22:G31) -> 3729.93 | H32: =SUM(H22:H31) -> 3667.26 | I32: =SUM(I22:I31) -> 3340.84 | J32: =SUM(J22:J31) -> 3388.21 | ... N32: =SUM(N22:N31) -> 6831.09 | O32: =SUM(C32:N32) -> 49111.02
A34: Operating income | C34: =C18-C32 -> 856.99 | D34: =D18-D32 -> 1211.45 | E34: =E18-E32 -> 84.59 | F34: =F18-F32 -> 245.7 | G34: =G18-G32 -> 1249.11 | H34: =H18-H32 -> 1477.77 | I34: =I18-I32 -> 968.17 | J34: =J18-J32 -> 845.62 | ... N34: =N18-N32 -> 1747.85 | O34: =SUM(C34:N34) -> 13214.9
A35: Operating margin | C35: =IFERROR(C34/C11,0) -> 0.062934423 | D35: =IFERROR(D34/D11,0) -> 0.069678305 | E35: =IFERROR(E34/E11,0) -> 0.0055691766 | F35: =IFERROR(F34/F11,0) -> 0.016887097 | G35: =IFERROR(G34/G11,0) -> 0.077396557 | H35: =IFERROR(H34/H11,0) -> 0.087125576 | I35: =IFERROR(I34/I11,0) -> 0.070748819 | J35: =IFERROR(J34/J11,0) -> 0.059397067 | ... O35: =IFERROR(O34/O11,0) -> 0.065183388
A37: Net income | C37: =C34 -> 856.99 | D37: =D34 -> 1211.45 | E37: =E34 -> 84.59 | F37: =F34 -> 245.7 | G37: =G34 -> 1249.11 | H37: =H34 -> 1477.77 | I37: =I34 -> 968.17 | J37: =J34 -> 845.62 | ... N37: =N34 -> 1747.85 | O37: =SUM(C37:N37) -> 13214.9
A38: Net margin | C38: =IFERROR(C37/C11,0) -> 0.062934423 | D38: =IFERROR(D37/D11,0) -> 0.069678305 | E38: =IFERROR(E37/E11,0) -> 0.0055691766 | F38: =IFERROR(F37/F11,0) -> 0.016887097 | G38: =IFERROR(G37/G11,0) -> 0.077396557 | H38: =IFERROR(H37/H11,0) -> 0.087125576 | I38: =IFERROR(I37/I11,0) -> 0.070748819 | J38: =IFERROR(J37/J11,0) -> 0.059397067 | ... O38: =IFERROR(O37/O11,0) -> 0.065183388
A40: Memo
A41: EBITDA: operating income plus depreciation | C41: =C34+C31 -> 856.99 | D41: =D34+D31 -> 1257.2 | E41: =E34+E31 -> 130.34 | F41: =F34+F31 -> 291.45 | G41: =G34+G31 -> 1294.86 | H41: =H34+H31 -> 1523.52 | I41: =I34+I31 -> 1013.92 | J41: =J34+J31 -> 891.37 | ... N41: =N34+N31 -> 1793.6 | O41: =SUM(C41:N41) -> 13718.15
A42: Spending: COGS plus cash operating expenses | C42: =C16+C32-C31 -> 12760.2 | D42: =D16+D32-D31 -> 16129.13 | E42: =E16+E32-E31 -> 15058.62 | F42: =F16+F32-F31 -> 14258.12 | G42: =G16+G32-G31 -> 14844.23 | H42: =H16+H32-H31 -> 15437.86 | I42: =I16+I32-I31 -> 12670.69 | J42: =J16+J32-J31 -> 13345.36 | ... N42: =N16+N32-N31 -> 25027.04 | O42: =SUM(C42:N42) -> 189016.02

Sheet Monthly BS
A1: Monthly Balance Sheet
A2: Opening balance and every month end. USD.
A3: Illustrative figures for privacy: modeled on the business's size, channels and products, not its actual results
A4: USD | B4: Opening | C4: 45688 | D4: 45716 | E4: 45747 | F4: 45777 | G4: 45808 | H4: 45838 | I4: 45869 | J4: 45900 | K4: 45930 | L4: 45961 | M4: 45991 | N4: 46022
A5: Assets
A6: Cash | B6: ='Assumptions'!$B$10 -> 9000 | C6: ='Monthly CF'!C26 -> 4682.3971 | D6: ='Monthly CF'!D26 -> 7248.3204 | E6: ='Monthly CF'!E26 -> 6364.4223 | F6: ='Monthly CF'!F26 -> 5931.663 | G6: ='Monthly CF'!G26 -> 7390.649 | H6: ='Monthly CF'!H26 -> 6928.552 | I6: ='Monthly CF'!I26 -> 6234.8968 | J6: ='Monthly CF'!J26 -> 7184.9545 | ... N6: ='Monthly CF'!N26 -> 13286.169
A7: Accounts receivable | B7: ='Schedules'!B21 -> 2374 | C7: ='Schedules'!C21 -> 1317.7926 | D7: ='Schedules'!D21 -> 1862.8211 | E7: ='Schedules'!E21 -> 1469.8994 | F7: ='Schedules'!F21 -> 1454.957 | G7: ='Schedules'!G21 -> 1561.8474 | H7: ='Schedules'!H21 -> 1696.138 | I7: ='Schedules'!I21 -> 1324.3171 | ... N7: ='Schedules'!N21 -> 2595.5458
A8: Inventory | B8: ='Schedules'!B18 -> 700 | C8: ='Schedules'!C18 -> 275.45 | D8: ='Schedules'!D18 -> 2166.85 | E8: ='Schedules'!E18 -> 1738.2 | F8: ='Schedules'!F18 -> 1287.55 | G8: ='Schedules'!G18 -> 772.5 | H8: ='Schedules'!H18 -> 2564.15 | I8: ='Schedules'!I18 -> 2117.55 | ... N8: ='Schedules'!N18 -> 2197.75
A9: Total current assets | B9: =SUM(B6:B8) -> 12074 | C9: =SUM(C6:C8) -> 6275.6397 | D9: =SUM(D6:D8) -> 11277.991 | E9: =SUM(E6:E8) -> 9572.5216 | F9: =SUM(F6:F8) -> 8674.17 | G9: =SUM(G6:G8) -> 9724.9965 | H9: =SUM(H6:H8) -> 11188.84 | I9: =SUM(I6:I8) -> 9676.7639 | ... N9: =SUM(N6:N8) -> 18079.465
A10: Equipment, net | B10: ='Schedules'!B12 -> 0 | C10: ='Schedules'!C12 -> 1647 | D10: ='Schedules'!D12 -> 1601.25 | E10: ='Schedules'!E12 -> 1555.5 | F10: ='Schedules'!F12 -> 1509.75 | G10: ='Schedules'!G12 -> 1464 | H10: ='Schedules'!H12 -> 1418.25 | I10: ='Schedules'!I12 -> 1372.5 | ... N10: ='Schedules'!N12 -> 1143.75
A11: Total assets | B11: =B9+B10 -> 12074 | C11: =C9+C10 -> 7922.6397 | D11: =D9+D10 -> 12879.241 | E11: =E9+E10 -> 11128.022 | F11: =F9+F10 -> 10183.92 | G11: =G9+G10 -> 11188.996 | H11: =H9+H10 -> 12607.09 | I11: =I9+I10 -> 11049.264 | ... N11: =N9+N10 -> 19223.215
A13: Liabilities and members' equity
A14: Accounts payable | B14: ='Schedules'!B22 -> 8019 | C14: ='Schedules'!C22 -> 4403.7097 | D14: ='Schedules'!D22 -> 6244.8214 | E14: ='Schedules'!E22 -> 5011.4516 | F14: ='Schedules'!F22 -> 4824 | G14: ='Schedules'!G22 -> 5150.8065 | H14: ='Schedules'!H22 -> 5654 | I14: ='Schedules'!I22 -> 4320.4839 | ... N14: ='Schedules'!N22 -> 8374.3548
A15: Sales tax payable | B15: ='Schedules'!B28 -> 708 | C15: ='Schedules'!C28 -> 64.94 | D15: ='Schedules'!D28 -> 218.98 | E15: ='Schedules'!E28 -> 366.54 | F15: ='Schedules'!F28 -> 114.19 | G15: ='Schedules'!G28 -> 293.35 | H15: ='Schedules'!H28 -> 480.48 | I15: ='Schedules'!I28 -> 38 | ... N15: ='Schedules'!N28 -> 786.96
A16: Total liabilities | B16: =B14+B15 -> 8727 | C16: =C14+C15 -> 4468.6497 | D16: =D14+D15 -> 6463.8014 | E16: =E14+E15 -> 5377.9916 | F16: =F14+F15 -> 4938.19 | G16: =G14+G15 -> 5444.1565 | H16: =H14+H15 -> 6134.48 | I16: =I14+I15 -> 4358.4839 | ... N16: =N14+N15 -> 9161.3148
A17: Members' equity | B17: ='Schedules'!B35 -> 3347 | C17: ='Schedules'!C35 -> 3453.99 | D17: ='Schedules'!D35 -> 6415.44 | E17: ='Schedules'!E35 -> 5750.03 | F17: ='Schedules'!F35 -> 5245.73 | G17: ='Schedules'!G35 -> 5744.84 | H17: ='Schedules'!H35 -> 6472.61 | I17: ='Schedules'!I35 -> 6690.78 | ... N17: ='Schedules'!N35 -> 10061.9
A18: Total liabilities and members' equity | B18: =B16+B17 -> 12074 | C18: =C16+C17 -> 7922.6397 | D18: =D16+D17 -> 12879.241 | E18: =E16+E17 -> 11128.022 | F18: =F16+F17 -> 10183.92 | G18: =G16+G17 -> 11188.996 | H18: =H16+H17 -> 12607.09 | I18: =I16+I17 -> 11049.264 | ... N18: =N16+N17 -> 19223.215
A20: Check: assets less liabilities and equity | B20: =ROUND(B11-B18,2) -> 0 | C20: =ROUND(C11-C18,2) -> 0 | D20: =ROUND(D11-D18,2) -> 0 | E20: =ROUND(E11-E18,2) -> 0 | F20: =ROUND(F11-F18,2) -> 0 | G20: =ROUND(G11-G18,2) -> 0 | H20: =ROUND(H11-H18,2) -> 0 | I20: =ROUND(I11-I18,2) -> 0 | ... N20: =ROUND(N11-N18,2) -> 0

Sheet Monthly CF
A1: Monthly Cash Flow
A2: Indirect method, by month. USD.
A3: Illustrative figures for privacy: modeled on the business's size, channels and products, not its actual results
A4: USD | C4: 45688 | D4: 45716 | E4: 45747 | F4: 45777 | G4: 45808 | H4: 45838 | I4: 45869 | J4: 45900 | K4: 45930 | L4: 45961 | M4: 45991 | N4: 46022 | O4: FY 2025
A5: Operating activities
A6: Net income | C6: ='Monthly P&L'!C37 -> 856.99 | D6: ='Monthly P&L'!D37 -> 1211.45 | E6: ='Monthly P&L'!E37 -> 84.59 | F6: ='Monthly P&L'!F37 -> 245.7 | G6: ='Monthly P&L'!G37 -> 1249.11 | H6: ='Monthly P&L'!H37 -> 1477.77 | I6: ='Monthly P&L'!I37 -> 968.17 | J6: ='Monthly P&L'!J37 -> 845.62 | ... N6: ='Monthly P&L'!N37 -> 1747.85 | O6: =SUM(C6:N6) -> 13214.9
A7: Depreciation | C7: ='Monthly P&L'!C31 -> 0 | D7: ='Monthly P&L'!D31 -> 45.75 | E7: ='Monthly P&L'!E31 -> 45.75 | F7: ='Monthly P&L'!F31 -> 45.75 | G7: ='Monthly P&L'!G31 -> 45.75 | H7: ='Monthly P&L'!H31 -> 45.75 | I7: ='Monthly P&L'!I31 -> 45.75 | J7: ='Monthly P&L'!J31 -> 45.75 | ... N7: ='Monthly P&L'!N31 -> 45.75 | O7: =SUM(C7:N7) -> 503.25
A8: Changes in working capital
A9: Accounts receivable | C9: ='Monthly BS'!B7-'Monthly BS'!C7 -> 1056.2074 | D9: ='Monthly BS'!C7-'Monthly BS'!D7 -> -545.02849 | E9: ='Monthly BS'!D7-'Monthly BS'!E7 -> 392.92172 | F9: ='Monthly BS'!E7-'Monthly BS'!F7 -> 14.942355 | G9: ='Monthly BS'!F7-'Monthly BS'!G7 -> -106.89042 | H9: ='Monthly BS'!G7-'Monthly BS'!H7 -> -134.29058 | I9: ='Monthly BS'!H7-'Monthly BS'!I7 -> 371.8209 | J9: ='Monthly BS'!I7-'Monthly BS'!J7 -> -53.430968 | ... N9: ='Monthly BS'!M7-'Monthly BS'!N7 -> -182.54281 | O9: =SUM(C9:N9) -> -221.54581
A10: Inventory | C10: ='Monthly BS'!B8-'Monthly BS'!C8 -> 424.55 | D10: ='Monthly BS'!C8-'Monthly BS'!D8 -> -1891.4 | E10: ='Monthly BS'!D8-'Monthly BS'!E8 -> 428.65 | F10: ='Monthly BS'!E8-'Monthly BS'!F8 -> 450.65 | G10: ='Monthly BS'!F8-'Monthly BS'!G8 -> 515.05 | H10: ='Monthly BS'!G8-'Monthly BS'!H8 -> -1791.65 | I10: ='Monthly BS'!H8-'Monthly BS'!I8 -> 446.6 | J10: ='Monthly BS'!I8-'Monthly BS'!J8 -> 412.9 | ... N10: ='Monthly BS'!M8-'Monthly BS'!N8 -> 934.7 | O10: =SUM(C10:N10) -> -1497.75
A11: Accounts payable | C11: ='Monthly BS'!C14-'Monthly BS'!B14 -> -3615.2903 | D11: ='Monthly BS'!D14-'Monthly BS'!C14 -> 1841.1118 | E11: ='Monthly BS'!E14-'Monthly BS'!D14 -> -1233.3698 | F11: ='Monthly BS'!F14-'Monthly BS'!E14 -> -187.45161 | G11: ='Monthly BS'!G14-'Monthly BS'!F14 -> 326.80645 | H11: ='Monthly BS'!H14-'Monthly BS'!G14 -> 503.19355 | I11: ='Monthly BS'!I14-'Monthly BS'!H14 -> -1333.5161 | J11: ='Monthly BS'!J14-'Monthly BS'!I14 -> 319.83871 | ... N11: ='Monthly BS'!N14-'Monthly BS'!M14 -> 273.85484 | O11: =SUM(C11:N11) -> 355.35484
A12: Sales tax payable | C12: ='Monthly BS'!C15-'Monthly BS'!B15 -> -643.06 | D12: ='Monthly BS'!D15-'Monthly BS'!C15 -> 154.04 | E12: ='Monthly BS'!E15-'Monthly BS'!D15 -> 147.56 | F12: ='Monthly BS'!F15-'Monthly BS'!E15 -> -252.35 | G12: ='Monthly BS'!G15-'Monthly BS'!F15 -> 179.16 | H12: ='Monthly BS'!H15-'Monthly BS'!G15 -> 187.13 | I12: ='Monthly BS'!I15-'Monthly BS'!H15 -> -442.48 | J12: ='Monthly BS'!J15-'Monthly BS'!I15 -> 129.38 | ... N12: ='Monthly BS'!N15-'Monthly BS'!M15 -> 279.81 | O12: =SUM(C12:N12) -> 78.96
A13: Net cash from operating activities | C13: =SUM(C6:C12) -> -1920.6029 | D13: =SUM(D6:D12) -> 815.92326 | E13: =SUM(E6:E12) -> -133.8981 | F13: =SUM(F6:F12) -> 317.24074 | G13: =SUM(G6:G12) -> 2208.986 | H13: =SUM(H6:H12) -> 287.90297 | I13: =SUM(I6:I12) -> 56.344774 | J13: =SUM(J6:J12) -> 1700.0577 | ... N13: =SUM(N6:N12) -> 3099.422 | O13: =SUM(C13:N13) -> 12433.169
A15: Investing activities
A16: Purchases of equipment | C16: =-'Data'!C32 -> -1647 | D16: =-'Data'!D32 -> 0 | E16: =-'Data'!E32 -> 0 | F16: =-'Data'!F32 -> 0 | G16: =-'Data'!G32 -> 0 | H16: =-'Data'!H32 -> 0 | I16: =-'Data'!I32 -> 0 | J16: =-'Data'!J32 -> 0 | ... N16: =-'Data'!N32 -> 0 | O16: =SUM(C16:N16) -> -1647
